Workbook

Sheet Contracts
B1: 17 | D1: Alan | G1: Fish | J1: Brock | M1: Chris N | P1: Chris S | S1: Devin | V1: John | Y1: Jon | AB1: Kevin | AE1: Evan | AH1: Matt | AK1: Mu | AN1: Mo | AQ1: Steve
A3: =CONCATENATE(B1+2008," Budget") | B3: 16
A4: =CONCATENATE(B1+2008," Budg.") | D4: ='AC (Dumpster Fires)'!K27 | G4: ='AW (Minor)'!$K$27 | J4: ='BL (Brockasauras)'!$K$27 | M4: ='CN (Nygaardians)'!$K$27 | P4: ='CS (Shag Dawgs)'!$K$27 | S4: ='DC (Cliff Lee Was Here)'!$K$27 | V4: ='JM (JMoney)'!$K$27 | Y4: ='JJ (metropolitans)'!$K$27 | AB4: ='KJ (Stat Sandwich)'!$K$27 | AE4: ='EP (Winning De)'!$K$27 | AH4: ='MB (Beckers Wreckers)'!$K$27 | AK4: ='MH (sabermutrics)'!$K$27 | AN4: ='MT (Tradezilla)'!$K$27 | AQ4: ='SM (Dawsyn)'!$K$27
A6: Contracts | D6: =IF('AC (Dumpster Fires)'!$Y$6>2006+$B$1,'AC (Dumpster Fires)'!$O$6,"") | G6: =IF('AW (Minor)'!$Y$6>2006+$B$1,'AW (Minor)'!$O$6,"") | J6: =IF('BL (Brockasauras)'!$Y$6>2006+$B$1,'BL (Brockasauras)'!$O$6,"") | M6: =IF('CN (Nygaardians)'!$Y$6>2006+$B$1,'CN (Nygaardians)'!$O$6,"") | P6: =IF('CS (Shag Dawgs)'!$Y$6>2006+$B$1,'CS (Shag Dawgs)'!$O$6,"") | S6: =IF('DC (Cliff Lee Was Here)'!$Y$6>2006+$B$1,'DC (Cliff Lee Was Here)'!$O$6,"") | V6: =IF('JM (JMoney)'!$Y$6>2006+$B$1,'JM (JMoney)'!$O$6,"") | Y6: =IF('JJ (metropolitans)'!$Y$6>2006+$B$1,'JJ (metropolitans)'!$O$6,"") | AB6: =IF('KJ (Stat Sandwich)'!$Y$6>2006+$B$1,'KJ (Stat Sandwich)'!$O$6,"") | AE6: =IF('EP (Winning De)'!$Y$6>2006+$B$1,'EP (Winning De)'!$O$6,"") | AH6: =IF('MB (Beckers Wreckers)'!$Y$6>2006+$B$1,'MB (Beckers Wreckers)'!$O$6,"") | AK6: =IF('MH (sabermutrics)'!$Y$6>2006+$B$1,'MH (sabermutrics)'!$O$6,"") | AN6: =IF('MT (Tradezilla)'!$Y$6>2006+$B$1,'MT (Tradezilla)'!$O$6,"") | AQ6: =IF('SM (Dawsyn)'!$Y$6>2006+$B$1,'SM (Dawsyn)'!$O$6,"")
D7: =IF('AC (Dumpster Fires)'!$Y$6>2006+$B$1,'AC (Dumpster Fires)'!$AA$6,"") | E7: =IF('AC (Dumpster Fires)'!$Y$6>2006+$B$1,'AC (Dumpster Fires)'!$Y$6,"") | G7: =IF('AW (Minor)'!$Y$6>2006+$B$1,'AW (Minor)'!$AA$6,"") | H7: =IF('AW (Minor)'!$Y$6>2006+$B$1,'AW (Minor)'!$Y$6,"") | J7: =IF('BL (Brockasauras)'!$Y$6>2006+$B$1,'BL (Brockasauras)'!$AA$6,"") | K7: =IF('BL (Brockasauras)'!$Y$6>2006+$B$1,'BL (Brockasauras)'!$Y$6,"") | M7: =IF('CN (Nygaardians)'!$Y$6>2006+$B$1,'CN (Nygaardians)'!$AA$6,"") | N7: =IF('CN (Nygaardians)'!$Y$6>2006+$B$1,'CN (Nygaardians)'!$Y$6,"") | P7: =IF('CS (Shag Dawgs)'!$Y$6>2006+$B$1,'CS (Shag Dawgs)'!$AA$6,"") | Q7: =IF('CS (Shag Dawgs)'!$Y$6>2006+$B$1,'CS (Shag Dawgs)'!$Y$6,"") | S7: =IF('DC (Cliff Lee Was Here)'!$Y$6>2006+$B$1,'DC (Cliff Lee Was Here)'!$AA$6,"") | T7: =IF('DC (Cliff Lee Was Here)'!$Y$6>2006+$B$1,'DC (Cliff Lee Was Here)'!$Y$6,"") | V7: =IF('JM (JMoney)'!$Y$6>2006+$B$1,'JM (JMoney)'!$AA$6,"") | W7: =IF('JM (JMoney)'!$Y$6>2006+$B$1,'JM (JMoney)'!$Y$6,"") | Y7: =IF('JJ (metropolitans)'!$Y$6>2006+$B$1,'JJ (metropolitans)'!$AA$6,"") | Z7: =IF('JJ (metropolitans)'!$Y$6>2006+$B$1,'JJ (metropolitans)'!$Y$6,"") | AB7: =IF('KJ (Stat Sandwich)'!$Y$6>2006+$B$1,'KJ (Stat Sandwich)'!$AA$6,"") | AC7: =IF('KJ (Stat Sandwich)'!$Y$6>2006+$B$1,'KJ (Stat Sandwich)'!$Y$6,"") | AE7: =IF('EP (Winning De)'!$Y$6>2006+$B$1,'EP (Winning De)'!$AA$6,"") | AF7: =IF('EP (Winning De)'!$Y$6>2006+$B$1,'EP (Winning De)'!$Y$6,"") | AH7: =IF('MB (Beckers Wreckers)'!$Y$6>2006+$B$1,'MB (Beckers Wreckers)'!$AA$6,"") | AI7: =IF('MB (Beckers Wreckers)'!$Y$6>2006+$B$1,'MB (Beckers Wreckers)'!$Y$6,"") | AK7: =IF('MH (sabermutrics)'!$Y$6>2006+$B$1,'MH (sabermutrics)'!$AA$6,"") | AL7: =IF('MH (sabermutrics)'!$Y$6>2006+$B$1,'MH (sabermutrics)'!$Y$6,"") | AN7: =IF('MT (Tradezilla)'!$Y$6>2006+$B$1,'MT (Tradezilla)'!$AA$6,"") | AO7: =IF('MT (Tradezilla)'!$Y$6>2006+$B$1,'MT (Tradezilla)'!$Y$6,"") | AQ7: =IF('SM (Dawsyn)'!$Y$6>2006+$B$1,'SM (Dawsyn)'!$AA$6,"") | AR7: =IF('SM (Dawsyn)'!$Y$6>2006+$B$1,'SM (Dawsyn)'!$Y$6,"")
D8: =IF('AC (Dumpster Fires)'!$Y$9>2006+$B$1,'AC (Dumpster Fires)'!$O$9,"") | G8: =IF('AW (Minor)'!$Y$9>2006+$B$1,'AW (Minor)'!$O$9,"") | J8: =IF('BL (Brockasauras)'!$Y$9>2006+$B$1,'BL (Brockasauras)'!$O$9,"") | M8: =IF('CN (Nygaardians)'!$Y$9>2006+$B$1,'CN (Nygaardians)'!$O$9,"") | P8: =IF('CS (Shag Dawgs)'!$Y$9>2006+$B$1,'CS (Shag Dawgs)'!$O$9,"") | S8: =IF('DC (Cliff Lee Was Here)'!$Y$9>2006+$B$1,'DC (Cliff Lee Was Here)'!$O$9,"") | V8: =IF('JM (JMoney)'!$Y$9>2006+$B$1,'JM (JMoney)'!$O$9,"") | Y8: =IF('JJ (metropolitans)'!$Y$9>2006+$B$1,'JJ (metropolitans)'!$O$9,"") | AB8: =IF('KJ (Stat Sandwich)'!$Y$9>2006+$B$1,'KJ (Stat Sandwich)'!$O$9,"") | AE8: =IF('EP (Winning De)'!$Y$9>2006+$B$1,'EP (Winning De)'!$O$9,"") | AH8: =IF('MB (Beckers Wreckers)'!$Y$9>2006+$B$1,'MB (Beckers Wreckers)'!$O$9,"") | AK8: =IF('MH (sabermutrics)'!$Y$9>2006+$B$1,'MH (sabermutrics)'!$O$9,"") | AN8: =IF('MT (Tradezilla)'!$Y$9>2006+$B$1,'MT (Tradezilla)'!$O$9,"") | AQ8: =IF('SM (Dawsyn)'!$Y$9>2006+$B$1,'SM (Dawsyn)'!$O$9,"")
D9: =IF('AC (Dumpster Fires)'!$Y$9>2006+$B$1,'AC (Dumpster Fires)'!$AA$9,"") | E9: =IF('AC (Dumpster Fires)'!$Y$9>2006+$B$1,'AC (Dumpster Fires)'!$Y$9,"") | G9: =IF('AW (Minor)'!$Y$9>2006+$B$1,'AW (Minor)'!$AA$9,"") | H9: =IF('AW (Minor)'!$Y$9>2006+$B$1,'AW (Minor)'!$Y$9,"") | J9: =IF('BL (Brockasauras)'!$Y$9>2006+$B$1,'BL (Brockasauras)'!$AA$9,"") | K9: =IF('BL (Brockasauras)'!$Y$9>2006+$B$1,'BL (Brockasauras)'!$Y$9,"") | M9: =IF('CN (Nygaardians)'!$Y$9>2006+$B$1,'CN (Nygaardians)'!$AA$9,"") | N9: =IF('CN (Nygaardians)'!$Y$9>2006+$B$1,'CN (Nygaardians)'!$Y$9,"") | P9: =IF('CS (Shag Dawgs)'!$Y$9>2006+$B$1,'CS (Shag Dawgs)'!$AA$9,"") | Q9: =IF('CS (Shag Dawgs)'!$Y$9>2006+$B$1,'CS (Shag Dawgs)'!$Y$9,"") | S9: =IF('DC (Cliff Lee Was Here)'!$Y$9>2006+$B$1,'DC (Cliff Lee Was Here)'!$AA$9,"") | T9: =IF('DC (Cliff Lee Was Here)'!$Y$9>2006+$B$1,'DC (Cliff Lee Was Here)'!$Y$9,"") | V9: =IF('JM (JMoney)'!$Y$9>2006+$B$1,'JM (JMoney)'!$AA$9,"") | W9: =IF('JM (JMoney)'!$Y$9>2006+$B$1,'JM (JMoney)'!$Y$9,"") | Y9: =IF('JJ (metropolitans)'!$Y$9>2006+$B$1,'JJ (metropolitans)'!$AA$9,"") | Z9: =IF('JJ (metropolitans)'!$Y$9>2006+$B$1,'JJ (metropolitans)'!$Y$9,"") | AB9: =IF('KJ (Stat Sandwich)'!$Y$9>2006+$B$1,'KJ (Stat Sandwich)'!$AA$9,"") | AC9: =IF('KJ (Stat Sandwich)'!$Y$9>2006+$B$1,'KJ (Stat Sandwich)'!$Y$9,"") | AE9: =IF('EP (Winning De)'!$Y$9>2006+$B$1,'EP (Winning De)'!$AA$9,"") | AF9: =IF('EP (Winning De)'!$Y$9>2006+$B$1,'EP (Winning De)'!$Y$9,"") | AH9: =IF('MB (Beckers Wreckers)'!$Y$9>2006+$B$1,'MB (Beckers Wreckers)'!$AA$9,"") | AI9: =IF('MB (Beckers Wreckers)'!$Y$9>2006+$B$1,'MB (Beckers Wreckers)'!$Y$9,"") | AK9: =IF('MH (sabermutrics)'!$Y$9>2006+$B$1,'MH (sabermutrics)'!$AA$9,"") | AL9: =IF('MH (sabermutrics)'!$Y$9>2006+$B$1,'MH (sabermutrics)'!$Y$9,"") | AN9: =IF('MT (Tradezilla)'!$Y$9>2006+$B$1,'MT (Tradezilla)'!$AA$9,"") | AO9: =IF('MT (Tradezilla)'!$Y$9>2006+$B$1,'MT (Tradezilla)'!$Y$9,"") | AQ9: =IF('SM (Dawsyn)'!$Y$9>2006+$B$1,'SM (Dawsyn)'!$AA$9,"") | AR9: =IF('SM (Dawsyn)'!$Y$9>2006+$B$1,'SM (Dawsyn)'!$Y$9,"")
D10: =IF('AC (Dumpster Fires)'!$Y$12>2006+$B$1,'AC (Dumpster Fires)'!$O$12,"") | G10: =IF('AW (Minor)'!$Y$12>2006+$B$1,'AW (Minor)'!$O$12,"") | J10: =IF('BL (Brockasauras)'!$Y$12>2006+$B$1,'BL (Brockasauras)'!$O$12,"") | M10: =IF('CN (Nygaardians)'!$Y$12>2006+$B$1,'CN (Nygaardians)'!$O$12,"") | P10: =IF('CS (Shag Dawgs)'!$Y$12>2006+$B$1,'CS (Shag Dawgs)'!$O$12,"") | S10: =IF('DC (Cliff Lee Was Here)'!$Y$12>2006+$B$1,'DC (Cliff Lee Was Here)'!$O$12,"") | V10: =IF('JM (JMoney)'!$Y$12>2006+$B$1,'JM (JMoney)'!$O$12,"") | Y10: =IF('JJ (metropolitans)'!$Y$12>2006+$B$1,'JJ (metropolitans)'!$O$12,"") | AB10: =IF('KJ (Stat Sandwich)'!$Y$12>2006+$B$1,'KJ (Stat Sandwich)'!$O$12,"") | AE10: =IF('EP (Winning De)'!$Y$12>2006+$B$1,'EP (Winning De)'!$O$12,"") | AH10: =IF('MB (Beckers Wreckers)'!$Y$12>2006+$B$1,'MB (Beckers Wreckers)'!$O$12,"") | AK10: =IF('MH (sabermutrics)'!$Y$12>2006+$B$1,'MH (sabermutrics)'!$O$12,"") | AN10: =IF('MT (Tradezilla)'!$Y$12>2006+$B$1,'MT (Tradezilla)'!$O$12,"") | AQ10: =IF('SM (Dawsyn)'!$Y$12>2006+$B$1,'SM (Dawsyn)'!$O$12,"")
D11: =IF('AC (Dumpster Fires)'!$Y$12>2006+$B$1,'AC (Dumpster Fires)'!$AA$12,"") | E11: =IF('AC (Dumpster Fires)'!$Y$12>2006+$B$1,'AC (Dumpster Fires)'!$Y$12,"") | G11: =IF('AW (Minor)'!$Y$12>2006+$B$1,'AW (Minor)'!$AA$12,"") | H11: =IF('AW (Minor)'!$Y$12>2006+$B$1,'AW (Minor)'!$Y$12,"") | J11: =IF('BL (Brockasauras)'!$Y$12>2006+$B$1,'BL (Brockasauras)'!$AA$12,"") | K11: =IF('BL (Brockasauras)'!$Y$12>2006+$B$1,'BL (Brockasauras)'!$Y$12,"") | M11: =IF('CN (Nygaardians)'!$Y$12>2006+$B$1,'CN (Nygaardians)'!$AA$12,"") | N11: =IF('CN (Nygaardians)'!$Y$12>2006+$B$1,'CN (Nygaardians)'!$Y$12,"") | P11: =IF('CS (Shag Dawgs)'!$Y$12>2006+$B$1,'CS (Shag Dawgs)'!$AA$12,"") | Q11: =IF('CS (Shag Dawgs)'!$Y$12>2006+$B$1,'CS (Shag Dawgs)'!$Y$12,"") | S11: =IF('DC (Cliff Lee Was Here)'!$Y$12>2006+$B$1,'DC (Cliff Lee Was Here)'!$AA$12,"") | T11: =IF('DC (Cliff Lee Was Here)'!$Y$12>2006+$B$1,'DC (Cliff Lee Was Here)'!$Y$12,"") | V11: =IF('JM (JMoney)'!$Y$12>2006+$B$1,'JM (JMoney)'!$AA$12,"") | W11: =IF('JM (JMoney)'!$Y$12>2006+$B$1,'JM (JMoney)'!$Y$12,"") | Y11: =IF('JJ (metropolitans)'!$Y$12>2006+$B$1,'JJ (metropolitans)'!$AA$12,"") | Z11: =IF('JJ (metropolitans)'!$Y$12>2006+$B$1,'JJ (metropolitans)'!$Y$12,"") | AB11: =IF('KJ (Stat Sandwich)'!$Y$12>2006+$B$1,'KJ (Stat Sandwich)'!$AA$12,"") | AC11: =IF('KJ (Stat Sandwich)'!$Y$12>2006+$B$1,'KJ (Stat Sandwich)'!$Y$12,"") | AE11: =IF('EP (Winning De)'!$Y$12>2006+$B$1,'EP (Winning De)'!$AA$12,"") | AF11: =IF('EP (Winning De)'!$Y$12>2006+$B$1,'EP (Winning De)'!$Y$12,"") | AH11: =IF('MB (Beckers Wreckers)'!$Y$12>2006+$B$1,'MB (Beckers Wreckers)'!$AA$12,"") | AI11: =IF('MB (Beckers Wreckers)'!$Y$12>2006+$B$1,'MB (Beckers Wreckers)'!$Y$12,"") | AK11: =IF('MH (sabermutrics)'!$Y$12>2006+$B$1,'MH (sabermutrics)'!$AA$12,"") | AL11: =IF('MH (sabermutrics)'!$Y$12>2006+$B$1,'MH (sabermutrics)'!$Y$12,"") | AN11: =IF('MT (Tradezilla)'!$Y$12>2006+$B$1,'MT (Tradezilla)'!$AA$12,"") | AO11: =IF('MT (Tradezilla)'!$Y$12>2006+$B$1,'MT (Tradezilla)'!$Y$12,"") | AQ11: =IF('SM (Dawsyn)'!$Y$12>2006+$B$1,'SM (Dawsyn)'!$AA$12,"") | AR11: =IF('SM (Dawsyn)'!$Y$12>2006+$B$1,'SM (Dawsyn)'!$Y$12,"")
D12: =IF('AC (Dumpster Fires)'!$Y$15>2006+$B$1,'AC (Dumpster Fires)'!$O$15,"") | G12: =IF('AW (Minor)'!$Y$15>2006+$B$1,'AW (Minor)'!$O$15,"") | J12: =IF('BL (Brockasauras)'!$Y$15>2006+$B$1,'BL (Brockasauras)'!$O$15,"") | M12: =IF('CN (Nygaardians)'!$Y$12>2006+$B$1,'CN (Nygaardians)'!$O$15,"") | P12: =IF('CS (Shag Dawgs)'!$Y$15>2006+$B$1,'CS (Shag Dawgs)'!$O$15,"") | S12: =IF('DC (Cliff Lee Was Here)'!$Y$15>2006+$B$1,'DC (Cliff Lee Was Here)'!$O$15,"") | V12: =IF('JM (JMoney)'!$Y$15>2006+$B$1,'JM (JMoney)'!$O$15,"") | Y12: =IF('JJ (metropolitans)'!$Y$15>2006+$B$1,'JJ (metropolitans)'!$O$15,"") | AB12: =IF('KJ (Stat Sandwich)'!$Y$15>2006+$B$1,'KJ (Stat Sandwich)'!$O$15,"") | AE12: =IF('EP (Winning De)'!$Y$15>2006+$B$1,'EP (Winning De)'!$O$15,"") | AH12: =IF('MB (Beckers Wreckers)'!$Y$15>2006+$B$1,'MB (Beckers Wreckers)'!$O$15,"") | AK12: =IF('MH (sabermutrics)'!$Y$15>2006+$B$1,'MH (sabermutrics)'!$O$15,"") | AN12: =IF('MT (Tradezilla)'!$Y$15>2006+$B$1,'MT (Tradezilla)'!$O$15,"") | AQ12: =IF('SM (Dawsyn)'!$Y$15>2006+$B$1,'SM (Dawsyn)'!$O$15,"")
D13: =IF('AC (Dumpster Fires)'!$Y$15>2006+$B$1,'AC (Dumpster Fires)'!$AA$15,"") | E13: =IF('AC (Dumpster Fires)'!$Y$15>2006+$B$1,'AC (Dumpster Fires)'!$Y$15,"") | G13: =IF('AW (Minor)'!$Y$15>2006+$B$1,'AW (Minor)'!$AA$15,"") | H13: =IF('AW (Minor)'!$Y$15>2006+$B$1,'AW (Minor)'!$Y$15,"") | J13: =IF('BL (Brockasauras)'!$Y$15>2006+$B$1,'BL (Brockasauras)'!$AA$15,"") | K13: =IF('BL (Brockasauras)'!$Y$15>2006+$B$1,'BL (Brockasauras)'!$Y$15,"") | M13: =IF('CN (Nygaardians)'!$Y$15>2006+$B$1,'CN (Nygaardians)'!$AA$15,"") | N13: =IF('CN (Nygaardians)'!$Y$15>2006+$B$1,'CN (Nygaardians)'!$Y$15,"") | P13: =IF('CS (Shag Dawgs)'!$Y$15>2006+$B$1,'CS (Shag Dawgs)'!$AA$15,"") | Q13: =IF('CS (Shag Dawgs)'!$Y$15>2006+$B$1,'CS (Shag Dawgs)'!$Y$15,"") | S13: =IF('DC (Cliff Lee Was Here)'!$Y$15>2006+$B$1,'DC (Cliff Lee Was Here)'!$AA$15,"") | T13: =IF('DC (Cliff Lee Was Here)'!$Y$15>2006+$B$1,'DC (Cliff Lee Was Here)'!$Y$15,"") | V13: =IF('JM (JMoney)'!$Y$15>2006+$B$1,'JM (JMoney)'!$AA$15,"") | W13: =IF('JM (JMoney)'!$Y$15>2006+$B$1,'JM (JMoney)'!$Y$15,"") | Y13: =IF('JJ (metropolitans)'!$Y$15>2006+$B$1,'JJ (metropolitans)'!$AA$15,"") | Z13: =IF('JJ (metropolitans)'!$Y$15>2006+$B$1,'JJ (metropolitans)'!$Y$15,"") | AB13: =IF('KJ (Stat Sandwich)'!$Y$15>2006+$B$1,'KJ (Stat Sandwich)'!$AA$15,"") | AC13: =IF('KJ (Stat Sandwich)'!$Y$15>2006+$B$1,'KJ (Stat Sandwich)'!$Y$15,"") | AE13: =IF('EP (Winning De)'!$Y$15>2006+$B$1,'EP (Winning De)'!$AA$15,"") | AF13: =IF('EP (Winning De)'!$Y$15>2006+$B$1,'EP (Winning De)'!$Y$15,"") | AH13: =IF('MB (Beckers Wreckers)'!$Y$15>2006+$B$1,'MB (Beckers Wreckers)'!$AA$15,"") | AI13: =IF('MB (Beckers Wreckers)'!$Y$15>2006+$B$1,'MB (Beckers Wreckers)'!$Y$15,"") | AK13: =IF('MH (sabermutrics)'!$Y$15>2006+$B$1,'MH (sabermutrics)'!$AA$15,"") | AL13: =IF('MH (sabermutrics)'!$Y$15>2006+$B$1,'MH (sabermutrics)'!$Y$15,"") | AN13: =IF('MT (Tradezilla)'!$Y$15>2006+$B$1,'MT (Tradezilla)'!$AA$15,"") | AO13: =IF('MT (Tradezilla)'!$Y$15>2006+$B$1,'MT (Tradezilla)'!$Y$15,"") | AQ13: =IF('SM (Dawsyn)'!$Y$15>2006+$B$1,'SM (Dawsyn)'!$AA$15,"") | AR13: =IF('SM (Dawsyn)'!$Y$15>2006+$B$1,'SM (Dawsyn)'!$Y$15,"")
D14: =IF('AC (Dumpster Fires)'!$Y$18>2006+$B$1,'AC (Dumpster Fires)'!$O$18,"") | G14: =IF('AW (Minor)'!$Y$18>2006+$B$1,'AW (Minor)'!$O$18,"") | J14: =IF('BL (Brockasauras)'!$Y$18>2006+$B$1,'BL (Brockasauras)'!$O$18,"") | M14: =IF('CN (Nygaardians)'!$Y$18>2006+$B$1,'CN (Nygaardians)'!$O$18,"") | P14: =IF('CS (Shag Dawgs)'!$Y$18>2006+$B$1,'CS (Shag Dawgs)'!$O$18,"") | S14: =IF('DC (Cliff Lee Was Here)'!$Y$18>2006+$B$1,'DC (Cliff Lee Was Here)'!$O$18,"") | V14: =IF('JM (JMoney)'!$Y$18>2006+$B$1,'JM (JMoney)'!$O$18,"") | Y14: =IF('JJ (metropolitans)'!$Y$18>2006+$B$1,'JJ (metropolitans)'!$O$18,"") | AB14: =IF('KJ (Stat Sandwich)'!$Y$18>2006+$B$1,'KJ (Stat Sandwich)'!$O$18,"") | AE14: =IF('EP (Winning De)'!$Y$18>2006+$B$1,'EP (Winning De)'!$O$18,"") | AH14: =IF('MB (Beckers Wreckers)'!$Y$18>2006+$B$1,'MB (Beckers Wreckers)'!$O$18,"") | AK14: =IF('MH (sabermutrics)'!$Y$18>2006+$B$1,'MH (sabermutrics)'!$O$18,"") | AN14: =IF('MT (Tradezilla)'!$Y$18>2006+$B$1,'MT (Tradezilla)'!$O$18,"") | AQ14: =IF('SM (Dawsyn)'!$Y$18>2006+$B$1,'SM (Dawsyn)'!$O$18,"")
D15: =IF('AC (Dumpster Fires)'!$Y$18>2006+$B$1,'AC (Dumpster Fires)'!$AA$18,"") | E15: =IF('AC (Dumpster Fires)'!$Y$18>2006+$B$1,'AC (Dumpster Fires)'!$Y$18,"") | G15: =IF('AW (Minor)'!$Y$18>2006+$B$1,'AW (Minor)'!$AA$18,"") | H15: =IF('AW (Minor)'!$Y$18>2006+$B$1,'AW (Minor)'!$Y$18,"") | J15: =IF('BL (Brockasauras)'!$Y$18>2006+$B$1,'BL (Brockasauras)'!$AA$18,"") | K15: =IF('BL (Brockasauras)'!$Y$18>2006+$B$1,'BL (Brockasauras)'!$Y$18,"") | M15: =IF('CN (Nygaardians)'!$Y$18>2006+$B$1,'CN (Nygaardians)'!$AA$18,"") | N15: =IF('CN (Nygaardians)'!$Y$18>2006+$B$1,'CN (Nygaardians)'!$Y$18,"") | P15: =IF('CS (Shag Dawgs)'!$Y$18>2006+$B$1,'CS (Shag Dawgs)'!$AA$18,"") | Q15: =IF('CS (Shag Dawgs)'!$Y$18>2006+$B$1,'CS (Shag Dawgs)'!$Y$18,"") | S15: =IF('DC (Cliff Lee Was Here)'!$Y$18>2006+$B$1,'DC (Cliff Lee Was Here)'!$AA$18,"") | T15: =IF('DC (Cliff Lee Was Here)'!$Y$18>2006+$B$1,'DC (Cliff Lee Was Here)'!$Y$18,"") | V15: =IF('JM (JMoney)'!$Y$18>2006+$B$1,'JM (JMoney)'!$AA$18,"") | W15: =IF('JM (JMoney)'!$Y$18>2006+$B$1,'JM (JMoney)'!$Y$18,"") | Y15: =IF('JJ (metropolitans)'!$Y$18>2006+$B$1,'JJ (metropolitans)'!$AA$18,"") | Z15: =IF('JJ (metropolitans)'!$Y$18>2006+$B$1,'JJ (metropolitans)'!$Y$18,"") | AB15: =IF('KJ (Stat Sandwich)'!$Y$18>2006+$B$1,'KJ (Stat Sandwich)'!$AA$18,"") | AC15: =IF('KJ (Stat Sandwich)'!$Y$18>2006+$B$1,'KJ (Stat Sandwich)'!$Y$18,"") | AE15: =IF('EP (Winning De)'!$Y$18>2006+$B$1,'EP (Winning De)'!$AA$18,"") | AF15: =IF('EP (Winning De)'!$Y$18>2006+$B$1,'EP (Winning De)'!$Y$18,"") | AH15: =IF('MB (Beckers Wreckers)'!$Y$18>2006+$B$1,'MB (Beckers Wreckers)'!$AA$18,"") | AI15: =IF('MB (Beckers Wreckers)'!$Y$18>2006+$B$1,'MB (Beckers Wreckers)'!$Y$18,"") | AK15: =IF('MH (sabermutrics)'!$Y$18>2006+$B$1,'MH (sabermutrics)'!$AA$18,"") | AL15: =IF('MH (sabermutrics)'!$Y$18>2006+$B$1,'MH (sabermutrics)'!$Y$18,"") | AN15: =IF('MT (Tradezilla)'!$Y$18>2006+$B$1,'MT (Tradezilla)'!$AA$18,"") | AO15: =IF('MT (Tradezilla)'!$Y$18>2006+$B$1,'MT (Tradezilla)'!$Y$18,"") | AQ15: =IF('SM (Dawsyn)'!$Y$18>2006+$B$1,'SM (Dawsyn)'!$AA$18,"") | AR15: =IF('SM (Dawsyn)'!$Y$18>2006+$B$1,'SM (Dawsyn)'!$Y$18,"")
D16: =IF('AC (Dumpster Fires)'!$Y$21>2006+$B$1,'AC (Dumpster Fires)'!$O$21,"") | G16: =IF('AW (Minor)'!$Y$21>2006+$B$1,'AW (Minor)'!$O$21,"") | J16: =IF('BL (Brockasauras)'!$Y$21>2006+$B$1,'BL (Brockasauras)'!$O$21,"") | M16: =IF('CN (Nygaardians)'!$Y$21>2006+$B$1,'CN (Nygaardians)'!$O$21,"") | P16: =IF('CS (Shag Dawgs)'!$Y$21>2006+$B$1,'CS (Shag Dawgs)'!$O$21,"") | S16: =IF('DC (Cliff Lee Was Here)'!$Y$21>2006+$B$1,'DC (Cliff Lee Was Here)'!$O$21,"") | V16: =IF('JM (JMoney)'!$Y$21>2006+$B$1,'JM (JMoney)'!$O$21,"") | Y16: =IF('JJ (metropolitans)'!$Y$21>2006+$B$1,'JJ (metropolitans)'!$O$21,"") | AB16: =IF('KJ (Stat Sandwich)'!$Y$21>2006+$B$1,'KJ (Stat Sandwich)'!$O$21,"") | AE16: =IF('EP (Winning De)'!$Y$21>2006+$B$1,'EP (Winning De)'!$O$21,"") | AH16: =IF('MB (Beckers Wreckers)'!$Y$21>2006+$B$1,'MB (Beckers Wreckers)'!$O$21,"") | AK16: =IF('MH (sabermutrics)'!$Y$21>2006+$B$1,'MH (sabermutrics)'!$O$21,"") | AN16: =IF('MT (Tradezilla)'!$Y$21>2006+$B$1,'MT (Tradezilla)'!$O$21,"") | AQ16: =IF('SM (Dawsyn)'!$Y$21>2006+$B$1,'SM (Dawsyn)'!$O$21,"")
D17: =IF('AC (Dumpster Fires)'!$Y$21>2006+$B$1,'AC (Dumpster Fires)'!$AA$21,"") | E17: =IF('AC (Dumpster Fires)'!$Y$21>2006+$B$1,'AC (Dumpster Fires)'!$Y$21,"") | G17: =IF('AW (Minor)'!$Y$21>2006+$B$1,'AW (Minor)'!$AA$21,"") | H17: =IF('AW (Minor)'!$Y$21>2006+$B$1,'AW (Minor)'!$Y$21,"") | J17: =IF('BL (Brockasauras)'!$Y$21>2006+$B$1,'BL (Brockasauras)'!$AA$21,"") | K17: =IF('BL (Brockasauras)'!$Y$21>2006+$B$1,'BL (Brockasauras)'!$Y$21,"") | M17: =IF('CN (Nygaardians)'!$Y$21>2006+$B$1,'CN (Nygaardians)'!$AA$21,"") | N17: =IF('CN (Nygaardians)'!$Y$21>2006+$B$1,'CN (Nygaardians)'!$Y$21,"") | P17: =IF('CS (Shag Dawgs)'!$Y$21>2006+$B$1,'CS (Shag Dawgs)'!$AA$21,"") | Q17: =IF('CS (Shag Dawgs)'!$Y$21>2006+$B$1,'CS (Shag Dawgs)'!$Y$21,"") | S17: =IF('DC (Cliff Lee Was Here)'!$Y$21>2006+$B$1,'DC (Cliff Lee Was Here)'!$AA$21,"") | T17: =IF('DC (Cliff Lee Was Here)'!$Y$21>2006+$B$1,'DC (Cliff Lee Was Here)'!$Y$21,"") | V17: =IF('JM (JMoney)'!$Y$21>2006+$B$1,'JM (JMoney)'!$AA$21,"") | W17: =IF('JM (JMoney)'!$Y$21>2006+$B$1,'JM (JMoney)'!$Y$21,"") | Y17: =IF('JJ (metropolitans)'!$Y$21>2006+$B$1,'JJ (metropolitans)'!$AA$21,"") | Z17: =IF('JJ (metropolitans)'!$Y$21>2006+$B$1,'JJ (metropolitans)'!$Y$21,"") | AB17: =IF('KJ (Stat Sandwich)'!$Y$21>2006+$B$1,'KJ (Stat Sandwich)'!$AA$21,"") | AC17: =IF('KJ (Stat Sandwich)'!$Y$21>2006+$B$1,'KJ (Stat Sandwich)'!$Y$21,"") | AE17: =IF('EP (Winning De)'!$Y$21>2006+$B$1,'EP (Winning De)'!$AA$21,"") | AF17: =IF('EP (Winning De)'!$Y$21>2006+$B$1,'EP (Winning De)'!$Y$21,"") | AH17: =IF('MB (Beckers Wreckers)'!$Y$21>2006+$B$1,'MB (Beckers Wreckers)'!$AA$21,"") | AI17: =IF('MB (Beckers Wreckers)'!$Y$21>2006+$B$1,'MB (Beckers Wreckers)'!$Y$21,"") | AK17: =IF('MH (sabermutrics)'!$Y$21>2006+$B$1,'MH (sabermutrics)'!$AA$21,"") | AL17: =IF('MH (sabermutrics)'!$Y$21>2006+$B$1,'MH (sabermutrics)'!$Y$21,"") | AN17: =IF('MT (Tradezilla)'!$Y$21>2006+$B$1,'MT (Tradezilla)'!$AA$21,"") | AO17: =IF('MT (Tradezilla)'!$Y$21>2006+$B$1,'MT (Tradezilla)'!$Y$21,"") | AQ17: =IF('SM (Dawsyn)'!$Y$21>2006+$B$1,'SM (Dawsyn)'!$AA$21,"") | AR17: =IF('SM (Dawsyn)'!$Y$21>2006+$B$1,'SM (Dawsyn)'!$Y$21,"")
D18: =IF('AC (Dumpster Fires)'!$Y$24>2006+$B$1,'AC (Dumpster Fires)'!$O$24,"") | G18: =IF('AW (Minor)'!$Y$24>2006+$B$1,'AW (Minor)'!$O$24,"") | J18: =IF('BL (Brockasauras)'!$Y$24>2006+$B$1,'BL (Brockasauras)'!$O$24,"") | M18: =IF('CN (Nygaardians)'!$Y$24>2006+$B$1,'CN (Nygaardians)'!$O$24,"") | P18: =IF('CS (Shag Dawgs)'!$Y$24>2006+$B$1,'CS (Shag Dawgs)'!$O$24,"") | S18: =IF('DC (Cliff Lee Was Here)'!$Y$24>2006+$B$1,'DC (Cliff Lee Was Here)'!$O$24,"") | V18: =IF('JM (JMoney)'!$Y$24>2006+$B$1,'JM (JMoney)'!$O$24,"") | Y18: =IF('JJ (metropolitans)'!$Y$24>2006+$B$1,'JJ (metropolitans)'!$O$24,"") | AB18: =IF('KJ (Stat Sandwich)'!$Y$24>2006+$B$1,'KJ (Stat Sandwich)'!$O$24,"") | AE18: =IF('EP (Winning De)'!$Y$24>2006+$B$1,'EP (Winning De)'!$O$24,"") | AH18: =IF('MB (Beckers Wreckers)'!$Y$24>2006+$B$1,'MB (Beckers Wreckers)'!$O$24,"") | AK18: =IF('MH (sabermutrics)'!$Y$24>2006+$B$1,'MH (sabermutrics)'!$O$24,"") | AN18: =IF('MT (Tradezilla)'!$Y$24>2006+$B$1,'MT (Tradezilla)'!$O$24,"") | AQ18: =IF('SM (Dawsyn)'!$Y$24>2006+$B$1,'SM (Dawsyn)'!$O$24,"")
D19: =IF('AC (Dumpster Fires)'!$Y$24>2006+$B$1,'AC (Dumpster Fires)'!$AA$24,"") | E19: =IF('AC (Dumpster Fires)'!$Y$24>2006+$B$1,'AC (Dumpster Fires)'!$Y$24,"") | G19: =IF('AW (Minor)'!$Y$24>2006+$B$1,'AW (Minor)'!$AA$24,"") | H19: =IF('AW (Minor)'!$Y$24>2006+$B$1,'AW (Minor)'!$Y$24,"") | J19: =IF('BL (Brockasauras)'!$Y$24>2006+$B$1,'BL (Brockasauras)'!$AA$24,"") | K19: =IF('BL (Brockasauras)'!$Y$24>2006+$B$1,'BL (Brockasauras)'!$Y$24,"") | M19: =IF('CN (Nygaardians)'!$Y$24>2006+$B$1,'CN (Nygaardians)'!$AA$24,"") | N19: =IF('CN (Nygaardians)'!$Y$24>2006+$B$1,'CN (Nygaardians)'!$Y$24,"") | P19: =IF('CS (Shag Dawgs)'!$Y$24>2006+$B$1,'CS (Shag Dawgs)'!$AA$24,"") | Q19: =IF('CS (Shag Dawgs)'!$Y$24>2006+$B$1,'CS (Shag Dawgs)'!$Y$24,"") | S19: =IF('DC (Cliff Lee Was Here)'!$Y$24>2006+$B$1,'DC (Cliff Lee Was Here)'!$AA$24,"") | T19: =IF('DC (Cliff Lee Was Here)'!$Y$24>2006+$B$1,'DC (Cliff Lee Was Here)'!$Y$24,"") | V19: =IF('JM (JMoney)'!$Y$24>2006+$B$1,'JM (JMoney)'!$AA$24,"") | W19: =IF('JM (JMoney)'!$Y$24>2006+$B$1,'JM (JMoney)'!$Y$24,"") | Y19: =IF('JJ (metropolitans)'!$Y$24>2006+$B$1,'JJ (metropolitans)'!$AA$24,"") | Z19: =IF('JJ (metropolitans)'!$Y$24>2006+$B$1,'JJ (metropolitans)'!$Y$24,"") | AB19: =IF('KJ (Stat Sandwich)'!$Y$24>2006+$B$1,'KJ (Stat Sandwich)'!$AA$24,"") | AC19: =IF('KJ (Stat Sandwich)'!$Y$24>2006+$B$1,'KJ (Stat Sandwich)'!$Y$24,"") | AE19: =IF('EP (Winning De)'!$Y$24>2006+$B$1,'EP (Winning De)'!$AA$24,"") | AF19: =IF('EP (Winning De)'!$Y$24>2006+$B$1,'EP (Winning De)'!$Y$24,"") | AH19: =IF('MB (Beckers Wreckers)'!$Y$24>2006+$B$1,'MB (Beckers Wreckers)'!$AA$24,"") | AI19: =IF('MB (Beckers Wreckers)'!$Y$24>2006+$B$1,'MB (Beckers Wreckers)'!$Y$24,"") | AK19: =IF('MH (sabermutrics)'!$Y$24>2006+$B$1,'MH (sabermutrics)'!$AA$24,"") | AL19: =IF('MH (sabermutrics)'!$Y$24>2006+$B$1,'MH (sabermutrics)'!$Y$24,"") | AN19: =IF('MT (Tradezilla)'!$Y$24>2006+$B$1,'MT (Tradezilla)'!$AA$24,"") | AO19: =IF('MT (Tradezilla)'!$Y$24>2006+$B$1,'MT (Tradezilla)'!$Y$24,"") | AQ19: =IF('SM (Dawsyn)'!$Y$24>2006+$B$1,'SM (Dawsyn)'!$AA$24,"") | AR19: =IF('SM (Dawsyn)'!$Y$24>2006+$B$1,'SM (Dawsyn)'!$Y$24,"")
D20: =IF('AC (Dumpster Fires)'!$Y$27>2006+$B$1,'AC (Dumpster Fires)'!$O$27,"") | G20: =IF('AW (Minor)'!$Y$27>2006+$B$1,'AW (Minor)'!$O$27,"") | J20: =IF('BL (Brockasauras)'!$Y$27>2006+$B$1,'BL (Brockasauras)'!$O$27,"") | M20: =IF('CN (Nygaardians)'!$Y$27>2006+$B$1,'CN (Nygaardians)'!$O$27,"") | P20: =IF('CS (Shag Dawgs)'!$Y$27>2006+$B$1,'CS (Shag Dawgs)'!$O$27,"") | S20: =IF('DC (Cliff Lee Was Here)'!$Y$27>2006+$B$1,'DC (Cliff Lee Was Here)'!$O$27,"") | V20: =IF('JM (JMoney)'!$Y$27>2006+$B$1,'JM (JMoney)'!$O$27,"") | Y20: =IF('JJ (metropolitans)'!$Y$27>2006+$B$1,'JJ (metropolitans)'!$O$27,"") | AB20: =IF('KJ (Stat Sandwich)'!$Y$27>2006+$B$1,'KJ (Stat Sandwich)'!$O$27,"") | AE20: =IF('EP (Winning De)'!$Y$27>2006+$B$1,'EP (Winning De)'!$O$27,"") | AH20: =IF('MB (Beckers Wreckers)'!$Y$27>2006+$B$1,'MB (Beckers Wreckers)'!$O$27,"") | AK20: =IF('MH (sabermutrics)'!$Y$27>2006+$B$1,'MH (sabermutrics)'!$O$27,"") | AN20: =IF('MT (Tradezilla)'!$Y$27>2006+$B$1,'MT (Tradezilla)'!$O$27,"") | AQ20: =IF('SM (Dawsyn)'!$Y$27>2006+$B$1,'SM (Dawsyn)'!$O$27,"")
D21: =IF('AC (Dumpster Fires)'!$Y$27>2006+$B$1,'AC (Dumpster Fires)'!$AA$27,"") | E21: =IF('AC (Dumpster Fires)'!$Y$27>2006+$B$1,'AC (Dumpster Fires)'!$Y$27,"") | G21: =IF('AW (Minor)'!$Y$27>2006+$B$1,'AW (Minor)'!$AA$27,"") | H21: =IF('AW (Minor)'!$Y$27>2006+$B$1,'AW (Minor)'!$Y$27,"") | J21: =IF('BL (Brockasauras)'!$Y$27>2006+$B$1,'BL (Brockasauras)'!$AA$27,"") | K21: =IF('BL (Brockasauras)'!$Y$27>2006+$B$1,'BL (Brockasauras)'!$Y$27,"") | M21: =IF('CN (Nygaardians)'!$Y$27>2006+$B$1,'CN (Nygaardians)'!$AA$27,"") | N21: =IF('CN (Nygaardians)'!$Y$27>2006+$B$1,'CN (Nygaardians)'!$Y$27,"") | P21: =IF('CS (Shag Dawgs)'!$Y$27>2006+$B$1,'CS (Shag Dawgs)'!$AA$27,"") | Q21: =IF('CS (Shag Dawgs)'!$Y$27>2006+$B$1,'CS (Shag Dawgs)'!$Y$27,"") | S21: =IF('DC (Cliff Lee Was Here)'!$Y$27>2006+$B$1,'DC (Cliff Lee Was Here)'!$AA$27,"") | T21: =IF('DC (Cliff Lee Was Here)'!$Y$27>2006+$B$1,'DC (Cliff Lee Was Here)'!$Y$27,"") | V21: =IF('JM (JMoney)'!$Y$27>2006+$B$1,'JM (JMoney)'!$AA$27,"") | W21: =IF('JM (JMoney)'!$Y$27>2006+$B$1,'JM (JMoney)'!$Y$27,"") | Y21: =IF('JJ (metropolitans)'!$Y$27>2006+$B$1,'JJ (metropolitans)'!$AA$27,"") | Z21: =IF('JJ (metropolitans)'!$Y$27>2006+$B$1,'JJ (metropolitans)'!$Y$27,"") | AB21: =IF('KJ (Stat Sandwich)'!$Y$27>2006+$B$1,'KJ (Stat Sandwich)'!$AA$27,"") | AC21: =IF('KJ (Stat Sandwich)'!$Y$27>2006+$B$1,'KJ (Stat Sandwich)'!$Y$27,"") | AE21: =IF('EP (Winning De)'!$Y$27>2006+$B$1,'EP (Winning De)'!$AA$27,"") | AF21: =IF('EP (Winning De)'!$Y$27>2006+$B$1,'EP (Winning De)'!$Y$27,"") | AH21: =IF('MB (Beckers Wreckers)'!$Y$27>2006+$B$1,'MB (Beckers Wreckers)'!$AA$27,"") | AI21: =IF('MB (Beckers Wreckers)'!$Y$27>2006+$B$1,'MB (Beckers Wreckers)'!$Y$27,"") | AK21: =IF('MH (sabermutrics)'!$Y$27>2006+$B$1,'MH (sabermutrics)'!$AA$27,"") | AL21: =IF('MH (sabermutrics)'!$Y$27>2006+$B$1,'MH (sabermutrics)'!$Y$27,"") | AN21: =IF('MT (Tradezilla)'!$Y$27>2006+$B$1,'MT (Tradezilla)'!$AA$27,"") | AO21: =IF('MT (Tradezilla)'!$Y$27>2006+$B$1,'MT (Tradezilla)'!$Y$27,"") | AQ21: =IF('SM (Dawsyn)'!$Y$27>2006+$B$1,'SM (Dawsyn)'!$AA$27,"") | AR21: =IF('SM (Dawsyn)'!$Y$27>2006+$B$1,'SM (Dawsyn)'!$Y$27,"")
D22: =IF('AC (Dumpster Fires)'!$Y$30>2006+$B$1,'AC (Dumpster Fires)'!$O$30,"") | G22: =IF('AW (Minor)'!$Y$30>2006+$B$1,'AW (Minor)'!$O$30,"") | J22: =IF('BL (Brockasauras)'!$Y$30>2006+$B$1,'BL (Brockasauras)'!$O$30,"") | M22: =IF('CN (Nygaardians)'!$Y$30>2006+$B$1,'CN (Nygaardians)'!$O$30,"") | P22: =IF('CS (Shag Dawgs)'!$Y$30>2006+$B$1,'CS (Shag Dawgs)'!$O$30,"") | S22: =IF('DC (Cliff Lee Was Here)'!$Y$30>2006+$B$1,'DC (Cliff Lee Was Here)'!$O$30,"") | V22: =IF('JM (JMoney)'!$Y$30>2006+$B$1,'JM (JMoney)'!$O$30,"") | Y22: =IF('JJ (metropolitans)'!$Y$30>2006+$B$1,'JJ (metropolitans)'!$O$30,"") | AB22: =IF('KJ (Stat Sandwich)'!$Y$30>2006+$B$1,'KJ (Stat Sandwich)'!$O$30,"") | AE22: =IF('EP (Winning De)'!$Y$30>2006+$B$1,'EP (Winning De)'!$O$30,"") | AH22: =IF('MB (Beckers Wreckers)'!$Y$30>2006+$B$1,'MB (Beckers Wreckers)'!$O$30,"") | AK22: =IF('MH (sabermutrics)'!$Y$30>2006+$B$1,'MH (sabermutrics)'!$O$30,"") | AN22: =IF('MT (Tradezilla)'!$Y$30>2006+$B$1,'MT (Tradezilla)'!$O$30,"") | AQ22: =IF('SM (Dawsyn)'!$Y$30>2006+$B$1,'SM (Dawsyn)'!$O$30,"")
D23: =IF('AC (Dumpster Fires)'!$Y$30>2006+$B$1,'AC (Dumpster Fires)'!$AA$30,"") | E23: =IF('AC (Dumpster Fires)'!$Y$30>2006+$B$1,'AC (Dumpster Fires)'!$Y$30,"") | G23: =IF('AW (Minor)'!$Y$30>2006+$B$1,'AW (Minor)'!$AA$30,"") | H23: =IF('AW (Minor)'!$Y$30>2006+$B$1,'AW (Minor)'!$Y$30,"") | J23: =IF('BL (Brockasauras)'!$Y$30>2006+$B$1,'BL (Brockasauras)'!$AA$30,"") | K23: =IF('BL (Brockasauras)'!$Y$30>2006+$B$1,'BL (Brockasauras)'!$Y$30,"") | M23: =IF('CN (Nygaardians)'!$Y$30>2006+$B$1,'CN (Nygaardians)'!$AA$30,"") | N23: =IF('CN (Nygaardians)'!$Y$30>2006+$B$1,'CN (Nygaardians)'!$Y$30,"") | P23: =IF('CS (Shag Dawgs)'!$Y$30>2006+$B$1,'CS (Shag Dawgs)'!$AA$30,"") | Q23: =IF('CS (Shag Dawgs)'!$Y$30>2006+$B$1,'CS (Shag Dawgs)'!$Y$30,"") | S23: =IF('DC (Cliff Lee Was Here)'!$Y$30>2006+$B$1,'DC (Cliff Lee Was Here)'!$AA$30,"") | T23: =IF('DC (Cliff Lee Was Here)'!$Y$30>2006+$B$1,'DC (Cliff Lee Was Here)'!$Y$30,"") | V23: =IF('JM (JMoney)'!$Y$30>2006+$B$1,'JM (JMoney)'!$AA$30,"") | W23: =IF('JM (JMoney)'!$Y$30>2006+$B$1,'JM (JMoney)'!$Y$30,"") | Y23: =IF('JJ (metropolitans)'!$Y$30>2006+$B$1,'JJ (metropolitans)'!$AA$30,"") | Z23: =IF('JJ (metropolitans)'!$Y$30>2006+$B$1,'JJ (metropolitans)'!$Y$30,"") | AB23: =IF('KJ (Stat Sandwich)'!$Y$30>2006+$B$1,'KJ (Stat Sandwich)'!$AA$30,"") | AC23: =IF('KJ (Stat Sandwich)'!$Y$30>2006+$B$1,'KJ (Stat Sandwich)'!$Y$30,"") | AE23: =IF('EP (Winning De)'!$Y$30>2006+$B$1,'EP (Winning De)'!$AA$30,"") | AF23: =IF('EP (Winning De)'!$Y$30>2006+$B$1,'EP (Winning De)'!$Y$30,"") | AH23: =IF('MB (Beckers Wreckers)'!$Y$30>2006+$B$1,'MB (Beckers Wreckers)'!$AA$30,"") | AI23: =IF('MB (Beckers Wreckers)'!$Y$30>2006+$B$1,'MB (Beckers Wreckers)'!$Y$30,"") | AK23: =IF('MH (sabermutrics)'!$Y$30>2006+$B$1,'MH (sabermutrics)'!$AA$30,"") | AL23: =IF('MH (sabermutrics)'!$Y$30>2006+$B$1,'MH (sabermutrics)'!$Y$30,"") | AN23: =IF('MT (Tradezilla)'!$Y$30>2006+$B$1,'MT (Tradezilla)'!$AA$30,"") | AO23: =IF('MT (Tradezilla)'!$Y$30>2006+$B$1,'MT (Tradezilla)'!$Y$30,"") | AQ23: =IF('SM (Dawsyn)'!$Y$30>2006+$B$1,'SM (Dawsyn)'!$AA$30,"") | AR23: =IF('SM (Dawsyn)'!$Y$30>2006+$B$1,'SM (Dawsyn)'!$Y$30,"")
D24: =IF('AC (Dumpster Fires)'!$Y$33>2006+$B$1,'AC (Dumpster Fires)'!$O$33,"") | G24: =IF('AW (Minor)'!$Y$33>2006+$B$1,'AW (Minor)'!$O$33,"") | J24: =IF('BL (Brockasauras)'!$Y$33>2006+$B$1,'BL (Brockasauras)'!$O$33,"") | M24: =IF('CN (Nygaardians)'!$Y$33>2006+$B$1,'CN (Nygaardians)'!$O$33,"") | P24: =IF('CS (Shag Dawgs)'!$Y$33>2006+$B$1,'CS (Shag Dawgs)'!$O$33,"") | S24: =IF('DC (Cliff Lee Was Here)'!$Y$33>2006+$B$1,'DC (Cliff Lee Was Here)'!$O$33,"") | V24: =IF('JM (JMoney)'!$Y$33>2006+$B$1,'JM (JMoney)'!$O$33,"") | Y24: =IF('JJ (metropolitans)'!$Y$33>2006+$B$1,'JJ (metropolitans)'!$O$33,"") | AB24: =IF('KJ (Stat Sandwich)'!$Y$33>2006+$B$1,'KJ (Stat Sandwich)'!$O$33,"") | AE24: =IF('EP (Winning De)'!$Y$33>2006+$B$1,'EP (Winning De)'!$O$33,"") | AH24: =IF('MB (Beckers Wreckers)'!$Y$33>2006+$B$1,'MB (Beckers Wreckers)'!$O$33,"") | AK24: =IF('MH (sabermutrics)'!$Y$33>2006+$B$1,'MH (sabermutrics)'!$O$33,"") | AN24: =IF('MT (Tradezilla)'!$Y$33>2006+$B$1,'MT (Tradezilla)'!$O$33,"") | AQ24: =IF('SM (Dawsyn)'!$Y$33>2006+$B$1,'SM (Dawsyn)'!$O$33,"")
D25: =IF('AC (Dumpster Fires)'!$Y$33>2006+$B$1,'AC (Dumpster Fires)'!$AA$33,"") | E25: =IF('AC (Dumpster Fires)'!$Y$33>2006+$B$1,'AC (Dumpster Fires)'!$Y$33,"") | G25: =IF('AW (Minor)'!$Y$33>2006+$B$1,'AW (Minor)'!$AA$33,"") | H25: =IF('AW (Minor)'!$Y$33>2006+$B$1,'AW (Minor)'!$Y$33,"") | J25: =IF('BL (Brockasauras)'!$Y$33>2006+$B$1,'BL (Brockasauras)'!$AA$33,"") | K25: =IF('BL (Brockasauras)'!$Y$33>2006+$B$1,'BL (Brockasauras)'!$Y$33,"") | M25: =IF('CN (Nygaardians)'!$Y$33>2006+$B$1,'CN (Nygaardians)'!$AA$33,"") | N25: =IF('CN (Nygaardians)'!$Y$33>2006+$B$1,'CN (Nygaardians)'!$Y$33,"") | P25: =IF('CS (Shag Dawgs)'!$Y$33>2006+$B$1,'CS (Shag Dawgs)'!$AA$33,"") | Q25: =IF('CS (Shag Dawgs)'!$Y$33>2006+$B$1,'CS (Shag Dawgs)'!$Y$33,"") | S25: =IF('DC (Cliff Lee Was Here)'!$Y$33>2006+$B$1,'DC (Cliff Lee Was Here)'!$AA$33,"") | T25: =IF('DC (Cliff Lee Was Here)'!$Y$33>2006+$B$1,'DC (Cliff Lee Was Here)'!$Y$33,"") | V25: =IF('JM (JMoney)'!$Y$33>2006+$B$1,'JM (JMoney)'!$AA$33,"") | W25: =IF('JM (JMoney)'!$Y$33>2006+$B$1,'JM (JMoney)'!$Y$33,"") | Y25: =IF('JJ (metropolitans)'!$Y$33>2006+$B$1,'JJ (metropolitans)'!$AA$33,"") | Z25: =IF('JJ (metropolitans)'!$Y$33>2006+$B$1,'JJ (metropolitans)'!$Y$33,"") | AB25: =IF('KJ (Stat Sandwich)'!$Y$33>2006+$B$1,'KJ (Stat Sandwich)'!$AA$33,"") | AC25: =IF('KJ (Stat Sandwich)'!$Y$33>2006+$B$1,'KJ (Stat Sandwich)'!$Y$33,"") | AE25: =IF('EP (Winning De)'!$Y$33>2006+$B$1,'EP (Winning De)'!$AA$33,"") | AF25: =IF('EP (Winning De)'!$Y$33>2006+$B$1,'EP (Winning De)'!$Y$33,"") | AH25: =IF('MB (Beckers Wreckers)'!$Y$33>2006+$B$1,'MB (Beckers Wreckers)'!$AA$33,"") | AI25: =IF('MB (Beckers Wreckers)'!$Y$33>2006+$B$1,'MB (Beckers Wreckers)'!$Y$33,"") | AK25: =IF('MH (sabermutrics)'!$Y$33>2006+$B$1,'MH (sabermutrics)'!$AA$33,"") | AL25: =IF('MH (sabermutrics)'!$Y$33>2006+$B$1,'MH (sabermutrics)'!$Y$33,"") | AN25: =IF('MT (Tradezilla)'!$Y$33>2006+$B$1,'MT (Tradezilla)'!$AA$33,"") | AO25: =IF('MT (Tradezilla)'!$Y$33>2006+$B$1,'MT (Tradezilla)'!$Y$33,"") | AQ25: =IF('SM (Dawsyn)'!$Y$33>2006+$B$1,'SM (Dawsyn)'!$AA$33,"") | AR25: =IF('SM (Dawsyn)'!$Y$33>2006+$B$1,'SM (Dawsyn)'!$Y$33,"")
D26: =IF('AC (Dumpster Fires)'!$Y$36>2006+$B$1,'AC (Dumpster Fires)'!$O$36,"") | G26: =IF('AW (Minor)'!$Y$36>2006+$B$1,'AW (Minor)'!$O$36,"") | J26: =IF('BL (Brockasauras)'!$Y$36>2006+$B$1,'BL (Brockasauras)'!$O$36,"") | M26: =IF('CN (Nygaardians)'!$Y$36>2006+$B$1,'CN (Nygaardians)'!$O$36,"") | P26: =IF('CS (Shag Dawgs)'!$Y$36>2006+$B$1,'CS (Shag Dawgs)'!$O$36,"") | S26: =IF('DC (Cliff Lee Was Here)'!$Y$36>2006+$B$1,'DC (Cliff Lee Was Here)'!$O$36,"") | V26: =IF('JM (JMoney)'!$Y$36>2006+$B$1,'JM (JMoney)'!$O$36,"") | Y26: =IF('JJ (metropolitans)'!$Y$36>2006+$B$1,'JJ (metropolitans)'!$O$36,"") | AB26: =IF('KJ (Stat Sandwich)'!$Y$36>2006+$B$1,'KJ (Stat Sandwich)'!$O$36,"") | AE26: =IF('EP (Winning De)'!$Y$36>2006+$B$1,'EP (Winning De)'!$O$36,"") | AH26: =IF('MB (Beckers Wreckers)'!$Y$36>2006+$B$1,'MB (Beckers Wreckers)'!$O$36,"") | AK26: =IF('MH (sabermutrics)'!$Y$36>2006+$B$1,'MH (sabermutrics)'!$O$36,"") | AN26: =IF('MT (Tradezilla)'!$Y$36>2006+$B$1,'MT (Tradezilla)'!$O$36,"") | AQ26: =IF('SM (Dawsyn)'!$Y$36>2006+$B$1,'SM (Dawsyn)'!$O$36,"")
D27: =IF('AC (Dumpster Fires)'!$Y$36>2006+$B$1,'AC (Dumpster Fires)'!$AA$36,"") | E27: =IF('AC (Dumpster Fires)'!$Y$36>2006+$B$1,'AC (Dumpster Fires)'!$Y$36,"") | G27: =IF('AW (Minor)'!$Y$36>2006+$B$1,'AW (Minor)'!$AA$36,"") | H27: =IF('AW (Minor)'!$Y$36>2006+$B$1,'AW (Minor)'!$Y$36,"") | J27: =IF('BL (Brockasauras)'!$Y$36>2006+$B$1,'BL (Brockasauras)'!$AA$36,"") | K27: =IF('BL (Brockasauras)'!$Y$36>2006+$B$1,'BL (Brockasauras)'!$Y$36,"") | M27: =IF('CN (Nygaardians)'!$Y$36>2006+$B$1,'CN (Nygaardians)'!$AA$36,"") | N27: =IF('CN (Nygaardians)'!$Y$36>2006+$B$1,'CN (Nygaardians)'!$Y$36,"") | P27: =IF('CS (Shag Dawgs)'!$Y$36>2006+$B$1,'CS (Shag Dawgs)'!$AA$36,"") | Q27: =IF('CS (Shag Dawgs)'!$Y$36>2006+$B$1,'CS (Shag Dawgs)'!$Y$36,"") | S27: =IF('DC (Cliff Lee Was Here)'!$Y$36>2006+$B$1,'DC (Cliff Lee Was Here)'!$AA$36,"") | T27: =IF('DC (Cliff Lee Was Here)'!$Y$36>2006+$B$1,'DC (Cliff Lee Was Here)'!$Y$36,"") | V27: =IF('JM (JMoney)'!$Y$36>2006+$B$1,'JM (JMoney)'!$AA$36,"") | W27: =IF('JM (JMoney)'!$Y$36>2006+$B$1,'JM (JMoney)'!$Y$36,"") | Y27: =IF('JJ (metropolitans)'!$Y$36>2006+$B$1,'JJ (metropolitans)'!$AA$36,"") | Z27: =IF('JJ (metropolitans)'!$Y$36>2006+$B$1,'JJ (metropolitans)'!$Y$36,"") | AB27: =IF('KJ (Stat Sandwich)'!$Y$36>2006+$B$1,'KJ (Stat Sandwich)'!$AA$36,"") | AC27: =IF('KJ (Stat Sandwich)'!$Y$36>2006+$B$1,'KJ (Stat Sandwich)'!$Y$36,"") | AE27: =IF('EP (Winning De)'!$Y$36>2006+$B$1,'EP (Winning De)'!$AA$36,"") | AF27: =IF('EP (Winning De)'!$Y$36>2006+$B$1,'EP (Winning De)'!$Y$36,"") | AH27: =IF('MB (Beckers Wreckers)'!$Y$36>2006+$B$1,'MB (Beckers Wreckers)'!$AA$36,"") | AI27: =IF('MB (Beckers Wreckers)'!$Y$36>2006+$B$1,'MB (Beckers Wreckers)'!$Y$36,"") | AK27: =IF('MH (sabermutrics)'!$Y$36>2006+$B$1,'MH (sabermutrics)'!$AA$36,"") | AL27: =IF('MH (sabermutrics)'!$Y$36>2006+$B$1,'MH (sabermutrics)'!$Y$36,"") | AN27: =IF('MT (Tradezilla)'!$Y$36>2006+$B$1,'MT (Tradezilla)'!$AA$36,"") | AO27: =IF('MT (Tradezilla)'!$Y$36>2006+$B$1,'MT (Tradezilla)'!$Y$36,"") | AQ27: =IF('SM (Dawsyn)'!$Y$36>2006+$B$1,'SM (Dawsyn)'!$AA$36,"") | AR27: =IF('SM (Dawsyn)'!$Y$36>2006+$B$1,'SM (Dawsyn)'!$Y$36,"")
D28: =IF('AC (Dumpster Fires)'!$Y$39>2006+$B$1,'AC (Dumpster Fires)'!$O$39,"") | G28: =IF('AW (Minor)'!$Y$39>2006+$B$1,'AW (Minor)'!$O$39,"") | J28: =IF('BL (Brockasauras)'!$Y$39>2006+$B$1,'BL (Brockasauras)'!$O$39,"") | M28: =IF('CN (Nygaardians)'!$Y$39>2006+$B$1,'CN (Nygaardians)'!$O$39,"") | P28: =IF('CS (Shag Dawgs)'!$Y$39>2006+$B$1,'CS (Shag Dawgs)'!$O$39,"") | S28: =IF('DC (Cliff Lee Was Here)'!$Y$39>2006+$B$1,'DC (Cliff Lee Was Here)'!$O$39,"") | V28: =IF('JM (JMoney)'!$Y$39>2006+$B$1,'JM (JMoney)'!$O$39,"") | Y28: =IF('JJ (metropolitans)'!$Y$39>2006+$B$1,'JJ (metropolitans)'!$O$39,"") | AB28: =IF('KJ (Stat Sandwich)'!$Y$39>2006+$B$1,'KJ (Stat Sandwich)'!$O$39,"") | AE28: =IF('EP (Winning De)'!$Y$39>2006+$B$1,'EP (Winning De)'!$O$39,"") | AH28: =IF('MB (Beckers Wreckers)'!$Y$39>2006+$B$1,'MB (Beckers Wreckers)'!$O$39,"") | AK28: =IF('MH (sabermutrics)'!$Y$39>2006+$B$1,'MH (sabermutrics)'!$O$39,"") | AN28: =IF('MT (Tradezilla)'!$Y$39>2006+$B$1,'MT (Tradezilla)'!$O$39,"") | AQ28: =IF('SM (Dawsyn)'!$Y$39>2006+$B$1,'SM (Dawsyn)'!$O$39,"")
D29: =IF('AC (Dumpster Fires)'!$Y$39>2006+$B$1,'AC (Dumpster Fires)'!$AA$39,"") | E29: =IF('AC (Dumpster Fires)'!$Y$39>2006+$B$1,'AC (Dumpster Fires)'!$Y$39,"") | G29: =IF('AW (Minor)'!$Y$39>2006+$B$1,'AW (Minor)'!$AA$39,"") | H29: =IF('AW (Minor)'!$Y$39>2006+$B$1,'AW (Minor)'!$Y$39,"") | J29: =IF('BL (Brockasauras)'!$Y$39>2006+$B$1,'BL (Brockasauras)'!$AA$39,"") | K29: =IF('BL (Brockasauras)'!$Y$39>2006+$B$1,'BL (Brockasauras)'!$Y$39,"") | M29: =IF('CN (Nygaardians)'!$Y$39>2006+$B$1,'CN (Nygaardians)'!$AA$39,"") | N29: =IF('CN (Nygaardians)'!$Y$39>2006+$B$1,'CN (Nygaardians)'!$Y$39,"") | P29: =IF('CS (Shag Dawgs)'!$Y$39>2006+$B$1,'CS (Shag Dawgs)'!$AA$39,"") | Q29: =IF('CS (Shag Dawgs)'!$Y$39>2006+$B$1,'CS (Shag Dawgs)'!$Y$39,"") | S29: =IF('DC (Cliff Lee Was Here)'!$Y$39>2006+$B$1,'DC (Cliff Lee Was Here)'!$AA$39,"") | T29: =IF('DC (Cliff Lee Was Here)'!$Y$39>2006+$B$1,'DC (Cliff Lee Was Here)'!$Y$39,"") | V29: =IF('JM (JMoney)'!$Y$39>2006+$B$1,'JM (JMoney)'!$AA$39,"") | W29: =IF('JM (JMoney)'!$Y$39>2006+$B$1,'JM (JMoney)'!$Y$39,"") | Y29: =IF('JJ (metropolitans)'!$Y$39>2006+$B$1,'JJ (metropolitans)'!$AA$39,"") | Z29: =IF('JJ (metropolitans)'!$Y$39>2006+$B$1,'JJ (metropolitans)'!$Y$39,"") | AB29: =IF('KJ (Stat Sandwich)'!$Y$39>2006+$B$1,'KJ (Stat Sandwich)'!$AA$39,"") | AC29: =IF('KJ (Stat Sandwich)'!$Y$39>2006+$B$1,'KJ (Stat Sandwich)'!$Y$39,"") | AE29: =IF('EP (Winning De)'!$Y$39>2006+$B$1,'EP (Winning De)'!$AA$39,"") | AF29: =IF('EP (Winning De)'!$Y$39>2006+$B$1,'EP (Winning De)'!$Y$39,"") | AH29: =IF('MB (Beckers Wreckers)'!$Y$39>2006+$B$1,'MB (Beckers Wreckers)'!$AA$39,"") | AI29: =IF('MB (Beckers Wreckers)'!$Y$39>2006+$B$1,'MB (Beckers Wreckers)'!$Y$39,"") | AK29: =IF('MH (sabermutrics)'!$Y$39>2006+$B$1,'MH (sabermutrics)'!$AA$39,"") | AL29: =IF('MH (sabermutrics)'!$Y$39>2006+$B$1,'MH (sabermutrics)'!$Y$39,"") | AN29: =IF('MT (Tradezilla)'!$Y$39>2006+$B$1,'MT (Tradezilla)'!$AA$39,"") | AO29: =IF('MT (Tradezilla)'!$Y$39>2006+$B$1,'MT (Tradezilla)'!$Y$39,"") | AQ29: =IF('SM (Dawsyn)'!$Y$39>2006+$B$1,'SM (Dawsyn)'!$AA$39,"") | AR29: =IF('SM (Dawsyn)'!$Y$39>2006+$B$1,'SM (Dawsyn)'!$Y$39,"")
D30: =IF('AC (Dumpster Fires)'!$Y$42>2006+$B$1,'AC (Dumpster Fires)'!$O$42,"") | G30: =IF('AW (Minor)'!$Y$42>2006+$B$1,'AW (Minor)'!$O$42,"") | J30: =IF('BL (Brockasauras)'!$Y$42>2006+$B$1,'BL (Brockasauras)'!$O$42,"") | M30: =IF('CN (Nygaardians)'!$Y$42>2006+$B$1,'CN (Nygaardians)'!$O$42,"") | P30: =IF('CS (Shag Dawgs)'!$Y$42>2006+$B$1,'CS (Shag Dawgs)'!$O$42,"") | S30: =IF('DC (Cliff Lee Was Here)'!$Y$42>2006+$B$1,'DC (Cliff Lee Was Here)'!$O$42,"") | V30: =IF('JM (JMoney)'!$Y$42>2006+$B$1,'JM (JMoney)'!$O$42,"") | Y30: =IF('JJ (metropolitans)'!$Y$42>2006+$B$1,'JJ (metropolitans)'!$O$42,"") | AB30: =IF('KJ (Stat Sandwich)'!$Y$42>2006+$B$1,'KJ (Stat Sandwich)'!$O$42,"") | AE30: =IF('EP (Winning De)'!$Y$42>2006+$B$1,'EP (Winning De)'!$O$42,"") | AH30: =IF('MB (Beckers Wreckers)'!$Y$42>2006+$B$1,'MB (Beckers Wreckers)'!$O$42,"") | AK30: =IF('MH (sabermutrics)'!$Y$42>2006+$B$1,'MH (sabermutrics)'!$O$42,"") | AN30: =IF('MT (Tradezilla)'!$Y$42>2006+$B$1,'MT (Tradezilla)'!$O$42,"") | AQ30: =IF('SM (Dawsyn)'!$Y$42>2006+$B$1,'SM (Dawsyn)'!$O$42,"")
D31: =IF('AC (Dumpster Fires)'!$Y$42>2006+$B$1,'AC (Dumpster Fires)'!$AA$42,"") | E31: =IF('AC (Dumpster Fires)'!$Y$42>2006+$B$1,'AC (Dumpster Fires)'!$Y$42,"") | G31: =IF('AW (Minor)'!$Y$42>2006+$B$1,'AW (Minor)'!$AA$42,"") | H31: =IF('AW (Minor)'!$Y$42>2006+$B$1,'AW (Minor)'!$Y$42,"") | J31: =IF('BL (Brockasauras)'!$Y$42>2006+$B$1,'BL (Brockasauras)'!$AA$42,"") | K31: =IF('BL (Brockasauras)'!$Y$42>2006+$B$1,'BL (Brockasauras)'!$Y$42,"") | M31: =IF('CN (Nygaardians)'!$Y$42>2006+$B$1,'CN (Nygaardians)'!$AA$42,"") | N31: =IF('CN (Nygaardians)'!$Y$42>2006+$B$1,'CN (Nygaardians)'!$Y$42,"") | P31: =IF('CS (Shag Dawgs)'!$Y$42>2006+$B$1,'CS (Shag Dawgs)'!$AA$42,"") | Q31: =IF('CS (Shag Dawgs)'!$Y$42>2006+$B$1,'CS (Shag Dawgs)'!$Y$42,"") | S31: =IF('DC (Cliff Lee Was Here)'!$Y$42>2006+$B$1,'DC (Cliff Lee Was Here)'!$AA$42,"") | T31: =IF('DC (Cliff Lee Was Here)'!$Y$42>2006+$B$1,'DC (Cliff Lee Was Here)'!$Y$42,"") | V31: =IF('JM (JMoney)'!$Y$42>2006+$B$1,'JM (JMoney)'!$AA$42,"") | W31: =IF('JM (JMoney)'!$Y$42>2006+$B$1,'JM (JMoney)'!$Y$42,"") | Y31: =IF('JJ (metropolitans)'!$Y$42>2006+$B$1,'JJ (metropolitans)'!$AA$42,"") | Z31: =IF('JJ (metropolitans)'!$Y$42>2006+$B$1,'JJ (metropolitans)'!$Y$42,"") | AB31: =IF('KJ (Stat Sandwich)'!$Y$42>2006+$B$1,'KJ (Stat Sandwich)'!$AA$42,"") | AC31: =IF('KJ (Stat Sandwich)'!$Y$42>2006+$B$1,'KJ (Stat Sandwich)'!$Y$42,"") | AE31: =IF('EP (Winning De)'!$Y$42>2006+$B$1,'EP (Winning De)'!$AA$42,"") | AF31: =IF('EP (Winning De)'!$Y$42>2006+$B$1,'EP (Winning De)'!$Y$42,"") | AH31: =IF('MB (Beckers Wreckers)'!$Y$42>2006+$B$1,'MB (Beckers Wreckers)'!$AA$42,"") | AI31: =IF('MB (Beckers Wreckers)'!$Y$42>2006+$B$1,'MB (Beckers Wreckers)'!$Y$42,"") | AK31: =IF('MH (sabermutrics)'!$Y$42>2006+$B$1,'MH (sabermutrics)'!$AA$42,"") | AL31: =IF('MH (sabermutrics)'!$Y$42>2006+$B$1,'MH (sabermutrics)'!$Y$42,"") | AN31: =IF('MT (Tradezilla)'!$Y$42>2006+$B$1,'MT (Tradezilla)'!$AA$42,"") | AO31: =IF('MT (Tradezilla)'!$Y$42>2006+$B$1,'MT (Tradezilla)'!$Y$42,"") | AQ31: =IF('SM (Dawsyn)'!$Y$42>2006+$B$1,'SM (Dawsyn)'!$AA$42,"") | AR31: =IF('SM (Dawsyn)'!$Y$42>2006+$B$1,'SM (Dawsyn)'!$Y$42,"")
D32: =IF('AC (Dumpster Fires)'!$Y$45>2006+$B$1,'AC (Dumpster Fires)'!$O$45,"") | G32: =IF('AW (Minor)'!$Y$45>2006+$B$1,'AW (Minor)'!$O$45,"") | J32: =IF('BL (Brockasauras)'!$Y$45>2006+$B$1,'BL (Brockasauras)'!$O$45,"") | M32: =IF('CN (Nygaardians)'!$Y$45>2006+$B$1,'CN (Nygaardians)'!$O$45,"") | P32: =IF('CS (Shag Dawgs)'!$Y$45>2006+$B$1,'CS (Shag Dawgs)'!$O$45,"") | S32: =IF('DC (Cliff Lee Was Here)'!$Y$45>2006+$B$1,'DC (Cliff Lee Was Here)'!$O$45,"") | V32: =IF('JM (JMoney)'!$Y$45>2006+$B$1,'JM (JMoney)'!$O$45,"") | Y32: =IF('JJ (metropolitans)'!$Y$45>2006+$B$1,'JJ (metropolitans)'!$O$45,"") | AB32: =IF('KJ (Stat Sandwich)'!$Y$45>2006+$B$1,'KJ (Stat Sandwich)'!$O$45,"") | AE32: =IF('EP (Winning De)'!$Y$45>2006+$B$1,'EP (Winning De)'!$O$45,"") | AH32: =IF('MB (Beckers Wreckers)'!$Y$45>2006+$B$1,'MB (Beckers Wreckers)'!$O$45,"") | AK32: =IF('MH (sabermutrics)'!$Y$45>2006+$B$1,'MH (sabermutrics)'!$O$45,"") | AN32: =IF('MT (Tradezilla)'!$Y$45>2006+$B$1,'MT (Tradezilla)'!$O$45,"") | AQ32: =IF('SM (Dawsyn)'!$Y$45>2006+$B$1,'SM (Dawsyn)'!$O$45,"")
D33: =IF('AC (Dumpster Fires)'!$Y$45>2006+$B$1,'AC (Dumpster Fires)'!$AA$45,"") | E33: =IF('AC (Dumpster Fires)'!$Y$45>2006+$B$1,'AC (Dumpster Fires)'!$Y$45,"") | G33: =IF('AW (Minor)'!$Y$45>2006+$B$1,'AW (Minor)'!$AA$45,"") | H33: =IF('AW (Minor)'!$Y$45>2006+$B$1,'AW (Minor)'!$Y$45,"") | J33: =IF('BL (Brockasauras)'!$Y$45>2006+$B$1,'BL (Brockasauras)'!$AA$45,"") | K33: =IF('BL (Brockasauras)'!$Y$45>2006+$B$1,'BL (Brockasauras)'!$Y$45,"") | M33: =IF('CN (Nygaardians)'!$Y$45>2006+$B$1,'CN (Nygaardians)'!$AA$45,"") | N33: =IF('CN (Nygaardians)'!$Y$45>2006+$B$1,'CN (Nygaardians)'!$Y$45,"") | P33: =IF('CS (Shag Dawgs)'!$Y$45>2006+$B$1,'CS (Shag Dawgs)'!$AA$45,"") | Q33: =IF('CS (Shag Dawgs)'!$Y$45>2006+$B$1,'CS (Shag Dawgs)'!$Y$45,"") | S33: =IF('DC (Cliff Lee Was Here)'!$Y$45>2006+$B$1,'DC (Cliff Lee Was Here)'!$AA$45,"") | T33: =IF('DC (Cliff Lee Was Here)'!$Y$45>2006+$B$1,'DC (Cliff Lee Was Here)'!$Y$45,"") | V33: =IF('JM (JMoney)'!$Y$45>2006+$B$1,'JM (JMoney)'!$AA$45,"") | W33: =IF('JM (JMoney)'!$Y$45>2006+$B$1,'JM (JMoney)'!$Y$45,"") | Y33: =IF('JJ (metropolitans)'!$Y$45>2006+$B$1,'JJ (metropolitans)'!$AA$45,"") | Z33: =IF('JJ (metropolitans)'!$Y$45>2006+$B$1,'JJ (metropolitans)'!$Y$45,"") | AB33: =IF('KJ (Stat Sandwich)'!$Y$45>2006+$B$1,'KJ (Stat Sandwich)'!$AA$45,"") | AC33: =IF('KJ (Stat Sandwich)'!$Y$45>2006+$B$1,'KJ (Stat Sandwich)'!$Y$45,"") | AE33: =IF('EP (Winning De)'!$Y$45>2006+$B$1,'EP (Winning De)'!$AA$45,"") | AF33: =IF('EP (Winning De)'!$Y$45>2006+$B$1,'EP (Winning De)'!$Y$45,"") | AH33: =IF('MB (Beckers Wreckers)'!$Y$45>2006+$B$1,'MB (Beckers Wreckers)'!$AA$45,"") | AI33: =IF('MB (Beckers Wreckers)'!$Y$45>2006+$B$1,'MB (Beckers Wreckers)'!$Y$45,"") | AK33: =IF('MH (sabermutrics)'!$Y$45>2006+$B$1,'MH (sabermutrics)'!$AA$45,"") | AL33: =IF('MH (sabermutrics)'!$Y$45>2006+$B$1,'MH (sabermutrics)'!$Y$45,"") | AN33: =IF('MT (Tradezilla)'!$Y$45>2006+$B$1,'MT (Tradezilla)'!$AA$45,"") | AO33: =IF('MT (Tradezilla)'!$Y$45>2006+$B$1,'MT (Tradezilla)'!$Y$45,"") | AQ33: =IF('SM (Dawsyn)'!$Y$45>2006+$B$1,'SM (Dawsyn)'!$AA$45,"") | AR33: =IF('SM (Dawsyn)'!$Y$45>2006+$B$1,'SM (Dawsyn)'!$Y$45,"")
D34: =IF('AC (Dumpster Fires)'!$Y$48>2006+$B$1,'AC (Dumpster Fires)'!$O$48,"") | G34: =IF('AW (Minor)'!$Y$48>2006+$B$1,'AW (Minor)'!$O$48,"") | J34: =IF('BL (Brockasauras)'!$Y$48>2006+$B$1,'BL (Brockasauras)'!$O$48,"") | M34: =IF('CN (Nygaardians)'!$Y$48>2006+$B$1,'CN (Nygaardians)'!$O$48,"") | P34: =IF('CS (Shag Dawgs)'!$Y$48>2006+$B$1,'CS (Shag Dawgs)'!$O$48,"") | S34: =IF('DC (Cliff Lee Was Here)'!$Y$48>2006+$B$1,'DC (Cliff Lee Was Here)'!$O$48,"") | V34: =IF('JM (JMoney)'!$Y$48>2006+$B$1,'JM (JMoney)'!$O$48,"") | Y34: =IF('JJ (metropolitans)'!$Y$48>2006+$B$1,'JJ (metropolitans)'!$O$48,"") | AB34: =IF('KJ (Stat Sandwich)'!$Y$48>2006+$B$1,'KJ (Stat Sandwich)'!$O$48,"") | AE34: =IF('EP (Winning De)'!$Y$48>2006+$B$1,'EP (Winning De)'!$O$48,"") | AH34: =IF('MB (Beckers Wreckers)'!$Y$48>2006+$B$1,'MB (Beckers Wreckers)'!$O$48,"") | AK34: =IF('MH (sabermutrics)'!$Y$48>2006+$B$1,'MH (sabermutrics)'!$O$48,"") | AN34: =IF('MT (Tradezilla)'!$Y$48>2006+$B$1,'MT (Tradezilla)'!$O$48,"") | AQ34: =IF('SM (Dawsyn)'!$Y$48>2006+$B$1,'SM (Dawsyn)'!$O$48,"")
D35: =IF('AC (Dumpster Fires)'!$Y$48>2006+$B$1,'AC (Dumpster Fires)'!$AA$48,"") | E35: =IF('AC (Dumpster Fires)'!$Y$48>2006+$B$1,'AC (Dumpster Fires)'!$Y$48,"") | G35: =IF('AW (Minor)'!$Y$48>2006+$B$1,'AW (Minor)'!$AA$48,"") | H35: =IF('AW (Minor)'!$Y$48>2006+$B$1,'AW (Minor)'!$Y$48,"") | J35: =IF('BL (Brockasauras)'!$Y$48>2006+$B$1,'BL (Brockasauras)'!$AA$48,"") | K35: =IF('BL (Brockasauras)'!$Y$48>2006+$B$1,'BL (Brockasauras)'!$Y$48,"") | M35: =IF('CN (Nygaardians)'!$Y$48>2006+$B$1,'CN (Nygaardians)'!$AA$48,"") | N35: =IF('CN (Nygaardians)'!$Y$48>2006+$B$1,'CN (Nygaardians)'!$Y$48,"") | P35: =IF('CS (Shag Dawgs)'!$Y$48>2006+$B$1,'CS (Shag Dawgs)'!$AA$48,"") | Q35: =IF('CS (Shag Dawgs)'!$Y$48>2006+$B$1,'CS (Shag Dawgs)'!$Y$48,"") | S35: =IF('DC (Cliff Lee Was Here)'!$Y$48>2006+$B$1,'DC (Cliff Lee Was Here)'!$AA$48,"") | T35: =IF('DC (Cliff Lee Was Here)'!$Y$48>2006+$B$1,'DC (Cliff Lee Was Here)'!$Y$48,"") | V35: =IF('JM (JMoney)'!$Y$48>2006+$B$1,'JM (JMoney)'!$AA$48,"") | W35: =IF('JM (JMoney)'!$Y$48>2006+$B$1,'JM (JMoney)'!$Y$48,"") | Y35: =IF('JJ (metropolitans)'!$Y$48>2006+$B$1,'JJ (metropolitans)'!$AA$48,"") | Z35: =IF('JJ (metropolitans)'!$Y$48>2006+$B$1,'JJ (metropolitans)'!$Y$48,"") | AB35: =IF('KJ (Stat Sandwich)'!$Y$48>2006+$B$1,'KJ (Stat Sandwich)'!$AA$48,"") | AC35: =IF('KJ (Stat Sandwich)'!$Y$48>2006+$B$1,'KJ (Stat Sandwich)'!$Y$48,"") | AE35: =IF('EP (Winning De)'!$Y$48>2006+$B$1,'EP (Winning De)'!$AA$48,"") | AF35: =IF('EP (Winning De)'!$Y$48>2006+$B$1,'EP (Winning De)'!$Y$48,"") | AH35: =IF('MB (Beckers Wreckers)'!$Y$48>2006+$B$1,'MB (Beckers Wreckers)'!$AA$48,"") | AI35: =IF('MB (Beckers Wreckers)'!$Y$48>2006+$B$1,'MB (Beckers Wreckers)'!$Y$48,"") | AK35: =IF('MH (sabermutrics)'!$Y$48>2006+$B$1,'MH (sabermutrics)'!$AA$48,"") | AL35: =IF('MH (sabermutrics)'!$Y$48>2006+$B$1,'MH (sabermutrics)'!$Y$48,"") | AN35: =IF('MT (Tradezilla)'!$Y$48>2006+$B$1,'MT (Tradezilla)'!$AA$48,"") | AO35: =IF('MT (Tradezilla)'!$Y$48>2006+$B$1,'MT (Tradezilla)'!$Y$48,"") | AQ35: =IF('SM (Dawsyn)'!$Y$48>2006+$B$1,'SM (Dawsyn)'!$AA$48,"") | AR35: =IF('SM (Dawsyn)'!$Y$48>2006+$B$1,'SM (Dawsyn)'!$Y$48,"")
A37: Farm | B37: MLB experience? (Yes/No) | D37: ='AC (Dumpster Fires)'!C38 | G37: ='AW (Minor)'!C38 | J37: =IF('BL (Brockasauras)'!$F$38>0,'BL (Brockasauras)'!$C$38,"") | M37: =IF('CN (Nygaardians)'!$F$38>0,'CN (Nygaardians)'!$C$38,"") | P37: =IF('CS (Shag Dawgs)'!$F$38>0,'CS (Shag Dawgs)'!$C$38,"") | S37: =IF('DC (Cliff Lee Was Here)'!$F$39>0,'DC (Cliff Lee Was Here)'!$C$38,"") | V37: =IF('JM (JMoney)'!$F$38>0,'JM (JMoney)'!$C$38,"") | Y37: =IF('JJ (metropolitans)'!$F$38>0,'JJ (metropolitans)'!$C$38,"") | AB37: =IF('KJ (Stat Sandwich)'!$F$38>0,'KJ (Stat Sandwich)'!$C$38,"") | AE37: =IF('EP (Winning De)'!$F$38>0,'EP (Winning De)'!$C$38,"") | AH37: =IF('MB (Beckers Wreckers)'!$F$38>0,'MB (Beckers Wreckers)'!$C$38,"") | AK37: =IF('MH (sabermutrics)'!$F$38>0,'MH (sabermutrics)'!$C$38,"") | AN37: =IF('MT (Tradezilla)'!$F$38>0,'MT (Tradezilla)'!$C$38,"") | AQ37: =IF('SM (Dawsyn)'!$F$38>0,'SM (Dawsyn)'!$C$38,"")
D38: ='AC (Dumpster Fires)'!F38 | E38: ='AC (Dumpster Fires)'!I38 | G38: ='AW (Minor)'!F38 | H38: ='AW (Minor)'!I38 | J38: =IF('BL (Brockasauras)'!$F$38>0,'BL (Brockasauras)'!$F$38,"") | K38: =IF('BL (Brockasauras)'!$F$38>0,'BL (Brockasauras)'!$I$38,"") | M38: =IF('CN (Nygaardians)'!$F$38>0,'CN (Nygaardians)'!$F$38,"") | N38: =IF('CN (Nygaardians)'!$F$38>0,'CN (Nygaardians)'!$I$38,"") | P38: =IF('CS (Shag Dawgs)'!$F$38>0,'CS (Shag Dawgs)'!$F$38,"") | Q38: =IF('CS (Shag Dawgs)'!$F$38>0,'CS (Shag Dawgs)'!$I$38,"") | S38: =IF('DC (Cliff Lee Was Here)'!$F$39>0,'DC (Cliff Lee Was Here)'!$F$39,"") | T38: =IF('DC (Cliff Lee Was Here)'!$F$39>0,'DC (Cliff Lee Was Here)'!$I$38,"") | V38: =IF('JM (JMoney)'!$F$38>0,'JM (JMoney)'!$F$38,"") | W38: =IF('JM (JMoney)'!$F$38>0,'JM (JMoney)'!$I$38,"") | Y38: =IF('JJ (metropolitans)'!$F$38>0,'JJ (metropolitans)'!$F$38,"") | Z38: =IF('JJ (metropolitans)'!$F$38>0,'JJ (metropolitans)'!$I$38,"") | AB38: =IF('KJ (Stat Sandwich)'!$F$38>0,'KJ (Stat Sandwich)'!$F$38,"") | AC38: =IF('KJ (Stat Sandwich)'!$F$38>0,'KJ (Stat Sandwich)'!$I$38,"") | AE38: =IF('EP (Winning De)'!$F$38>0,'EP (Winning De)'!$F$38,"") | AF38: =IF('EP (Winning De)'!$F$38>0,'EP (Winning De)'!$I$38,"") | AH38: =IF('MB (Beckers Wreckers)'!$F$38>0,'MB (Beckers Wreckers)'!$F$38,"") | AI38: =IF('MB (Beckers Wreckers)'!$F$38>0,'MB (Beckers Wreckers)'!$I$38,"") | AK38: =IF('MH (sabermutrics)'!$F$38>0,'MH (sabermutrics)'!$F$38,"") | AL38: =IF('MH (sabermutrics)'!$F$38>0,'MH (sabermutrics)'!$I$38,"") | AN38: =IF('MT (Tradezilla)'!$F$38>0,'MT (Tradezilla)'!$F$38,"") | AO38: =IF('MT (Tradezilla)'!$F$38>0,'MT (Tradezilla)'!$I$38,"") | AQ38: =IF('SM (Dawsyn)'!$F$38>0,'SM (Dawsyn)'!$F$38,"") | AR38: =IF('SM (Dawsyn)'!$F$38>0,'SM (Dawsyn)'!$I$38,"")
D39: ='AC (Dumpster Fires)'!C39 | G39: ='AW (Minor)'!C39 | J39: =IF('BL (Brockasauras)'!$F$39>0,'BL (Brockasauras)'!$C$39,"") | M39: =IF('CN (Nygaardians)'!$F$39>0,'CN (Nygaardians)'!$C$39,"") | P39: =IF('CS (Shag Dawgs)'!$F$39>0,'CS (Shag Dawgs)'!$C$39,"") | S39: =IF(#REF!>0,'DC (Cliff Lee Was Here)'!$C$39,"") | V39: =IF('JM (JMoney)'!$F$39>0,'JM (JMoney)'!$C$39,"") | Y39: =IF('JJ (metropolitans)'!$F$39>0,'JJ (metropolitans)'!$C$39,"") | AB39: =IF('KJ (Stat Sandwich)'!$F$39>0,'KJ (Stat Sandwich)'!$C$39,"") | AE39: =IF('EP (Winning De)'!$F$39>0,'EP (Winning De)'!$C$39,"") | AH39: =IF('MB (Beckers Wreckers)'!$F$39>0,'MB (Beckers Wreckers)'!$C$39,"") | AK39: =IF('MH (sabermutrics)'!$F$39>0,'MH (sabermutrics)'!$C$39,"") | AN39: =IF('MT (Tradezilla)'!$F$39>0,'MT (Tradezilla)'!$C$39,"") | AQ39: =IF('SM (Dawsyn)'!$F$39>0,'SM (Dawsyn)'!$C$39,"")
D40: ='AC (Dumpster Fires)'!F39 | E40: ='AC (Dumpster Fires)'!I39 | G40: ='AW (Minor)'!F39 | H40: ='AW (Minor)'!I39 | J40: =IF('BL (Brockasauras)'!$F$39>0,'BL (Brockasauras)'!$F$39,"") | K40: =IF('BL (Brockasauras)'!$F$39>0,'BL (Brockasauras)'!$I$39,"") | M40: =IF('CN (Nygaardians)'!$F$39>0,'CN (Nygaardians)'!$F$39,"") | N40: =IF('CN (Nygaardians)'!$F$39>0,'CN (Nygaardians)'!$I$39,"") | P40: =IF('CS (Shag Dawgs)'!$F$39>0,'CS (Shag Dawgs)'!$F$39,"") | Q40: =IF('CS (Shag Dawgs)'!$F$39>0,'CS (Shag Dawgs)'!$I$39,"") | S40: =IF(#REF!>0,#REF!,"") | T40: =IF(#REF!>0,'DC (Cliff Lee Was Here)'!$I$39,"") | V40: =IF('JM (JMoney)'!$F$39>0,'JM (JMoney)'!$F$39,"") | W40: =IF('JM (JMoney)'!$F$39>0,'JM (JMoney)'!$I$39,"") | Y40: =IF('JJ (metropolitans)'!$F$39>0,'JJ (metropolitans)'!$F$39,"") | Z40: =IF('JJ (metropolitans)'!$F$39>0,'JJ (metropolitans)'!$I$39,"") | AB40: =IF('KJ (Stat Sandwich)'!$F$39>0,'KJ (Stat Sandwich)'!$F$39,"") | AC40: =IF('KJ (Stat Sandwich)'!$F$39>0,'KJ (Stat Sandwich)'!$I$39,"") | AE40: =IF('EP (Winning De)'!$F$39>0,'EP (Winning De)'!$F$39,"") | AF40: =IF('EP (Winning De)'!$F$39>0,'EP (Winning De)'!$I$39,"") | AH40: =IF('MB (Beckers Wreckers)'!$F$39>0,'MB (Beckers Wreckers)'!$F$39,"") | AI40: =IF('MB (Beckers Wreckers)'!$F$39>0,'MB (Beckers Wreckers)'!$I$39,"") | AK40: =IF('MH (sabermutrics)'!$F$39>0,'MH (sabermutrics)'!$F$39,"") | AL40: =IF('MH (sabermutrics)'!$F$39>0,'MH (sabermutrics)'!$I$39,"") | AN40: =IF('MT (Tradezilla)'!$F$39>0,'MT (Tradezilla)'!$F$39,"") | AO40: =IF('MT (Tradezilla)'!$F$39>0,'MT (Tradezilla)'!$I$39,"") | AQ40: =IF('SM (Dawsyn)'!$F$39>0,'SM (Dawsyn)'!$F$39,"") | AR40: =IF('SM (Dawsyn)'!$F$39>0,'SM (Dawsyn)'!$I$39,"")
D41: ='AC (Dumpster Fires)'!C40 | G41: ='AW (Minor)'!C40 | J41: =IF('BL (Brockasauras)'!$F$40>0,'BL (Brockasauras)'!$C$40,"") | M41: =IF('CN (Nygaardians)'!$F$40>0,'CN (Nygaardians)'!$C$40,"") | P41: =IF('CS (Shag Dawgs)'!$F$40>0,'CS (Shag Dawgs)'!$C$40,"") | S41: =IF('DC (Cliff Lee Was Here)'!$F$40>0,'DC (Cliff Lee Was Here)'!$C$40,"") | V41: =IF('JM (JMoney)'!$F$40>0,'JM (JMoney)'!$C$40,"") | Y41: =IF('JJ (metropolitans)'!$F$40>0,'JJ (metropolitans)'!$C$40,"") | AB41: =IF('KJ (Stat Sandwich)'!$F$40>0,'KJ (Stat Sandwich)'!$C$40,"") | AE41: =IF('EP (Winning De)'!$F$40>0,'EP (Winning De)'!$C$40,"") | AH41: =IF('MB (Beckers Wreckers)'!$F$40>0,'MB (Beckers Wreckers)'!$C$40,"") | AK41: =IF('MH (sabermutrics)'!$F$40>0,'MH (sabermutrics)'!$C$40,"") | AN41: =IF('MT (Tradezilla)'!$F$40>0,'MT (Tradezilla)'!$C$40,"") | AQ41: =IF('SM (Dawsyn)'!$F$40>0,'SM (Dawsyn)'!$C$40,"")
D42: ='AC (Dumpster Fires)'!F40 | E42: ='AC (Dumpster Fires)'!I40 | G42: ='AW (Minor)'!F40 | H42: ='AW (Minor)'!I40 | J42: =IF('BL (Brockasauras)'!$F$40>0,'BL (Brockasauras)'!$F$40,"") | K42: =IF('BL (Brockasauras)'!$F$40>0,'BL (Brockasauras)'!$I$40,"") | M42: =IF('CN (Nygaardians)'!$F$40>0,'CN (Nygaardians)'!$F$40,"") | N42: =IF('CN (Nygaardians)'!$F$40>0,'CN (Nygaardians)'!$I$40,"") | P42: =IF('CS (Shag Dawgs)'!$F$40>0,'CS (Shag Dawgs)'!$F$40,"") | Q42: =IF('CS (Shag Dawgs)'!$F$40>0,'CS (Shag Dawgs)'!$I$40,"") | S42: =IF('DC (Cliff Lee Was Here)'!$F$40>0,'DC (Cliff Lee Was Here)'!$F$40,"") | T42: =IF('DC (Cliff Lee Was Here)'!$F$40>0,'DC (Cliff Lee Was Here)'!$I$40,"") | V42: =IF('JM (JMoney)'!$F$40>0,'JM (JMoney)'!$F$40,"") | W42: =IF('JM (JMoney)'!$F$40>0,'JM (JMoney)'!$I$40,"") | Y42: =IF('JJ (metropolitans)'!$F$40>0,'JJ (metropolitans)'!$F$40,"") | Z42: =IF('JJ (metropolitans)'!$F$40>0,'JJ (metropolitans)'!$I$40,"") | AB42: =IF('KJ (Stat Sandwich)'!$F$40>0,'KJ (Stat Sandwich)'!$F$40,"") | AC42: =IF('KJ (Stat Sandwich)'!$F$40>0,'KJ (Stat Sandwich)'!$I$40,"") | AE42: =IF('EP (Winning De)'!$F$40>0,'EP (Winning De)'!$F$40,"") | AF42: =IF('EP (Winning De)'!$F$39>0,'EP (Winning De)'!$I$39,"") | AH42: =IF('MB (Beckers Wreckers)'!$F$40>0,'MB (Beckers Wreckers)'!$F$40,"") | AI42: =IF('MB (Beckers Wreckers)'!$F$40>0,'MB (Beckers Wreckers)'!$I$40,"") | AK42: =IF('MH (sabermutrics)'!$F$40>0,'MH (sabermutrics)'!$F$40,"") | AL42: =IF('MH (sabermutrics)'!$F$40>0,'MH (sabermutrics)'!$I$40,"") | AN42: =IF('MT (Tradezilla)'!$F$40>0,'MT (Tradezilla)'!$F$40,"") | AO42: =IF('MT (Tradezilla)'!$F$40>0,'MT (Tradezilla)'!$I$40,"") | AQ42: =IF('SM (Dawsyn)'!$F$40>0,'SM (Dawsyn)'!$F$40,"") | AR42: =IF('SM (Dawsyn)'!$F$40>0,'SM (Dawsyn)'!$I$40,"")
D43: ='AC (Dumpster Fires)'!C41 | G43: ='AW (Minor)'!C41 | J43: =IF('BL (Brockasauras)'!$F$41>0,'BL (Brockasauras)'!$C$41,"") | M43: =IF('CN (Nygaardians)'!$F$41>0,'CN (Nygaardians)'!$C$41,"") | P43: =IF('CS (Shag Dawgs)'!$F$41>0,'CS (Shag Dawgs)'!$C$41,"") | S43: =IF('DC (Cliff Lee Was Here)'!$F$41>0,'DC (Cliff Lee Was Here)'!$C$41,"") | V43: =IF('JM (JMoney)'!$F$41>0,'JM (JMoney)'!$C$41,"") | Y43: =IF('JJ (metropolitans)'!$F$41>0,'JJ (metropolitans)'!$C$41,"") | AB43: =IF('KJ (Stat Sandwich)'!$F$41>0,'KJ (Stat Sandwich)'!$C$41,"") | AE43: =IF('EP (Winning De)'!$F$41>0,'EP (Winning De)'!$C$41,"") | AH43: =IF('MB (Beckers Wreckers)'!$F$41>0,'MB (Beckers Wreckers)'!$C$41,"") | AK43: =IF('MH (sabermutrics)'!$F$41>0,'MH (sabermutrics)'!$C$41,"") | AN43: =IF('MT (Tradezilla)'!$F$41>0,'MT (Tradezilla)'!$C$41,"") | AQ43: =IF('SM (Dawsyn)'!$F$41>0,'SM (Dawsyn)'!$C$41,"")
...

Sheet Farm Draft 2025
A2: Place | B2: Season Standings Order | C2: Pick Owners as of 2/15 | D2: Order | E2: Final Order | F2: Pick
A3: 7 | B3: Sabermutrics | C3: Sabermutrics | D3: 1
A4: 9 | B4: JMoney | C4: JMoney | D4: 2
A5: 11 | B5: Nygaardians | C5: JMoney | D5: 3
A6: 8 | B6: Brockasaurus | C6: Minor Legalities | D6: 4
A7: 10 | B7: Cliff Lee Was Here | C7: Cliff Lee Was Here | D7: 5
A8: 12 | B8: Winning DeLautery | C8: Winning DeLautery | D8: 6
A9: 13 | B9: Becker's Wreckers | C9: Becker's Wreckers | D9: 7
A10: 5 | B10: Tradezilla | C10: Cliff Lee Was Here | D10: 8
A11: 4 | B11: DAWSYN | C11: Minor Legalities | D11: 9
A12: 6 | B12: Dumpster Fire | C12: Dumpster Fire | D12: 10
A13: 14 | B13: Minor Legalities | C13: Minor Legalities | D13: 11
A14: 3 | B14: Metropolitans | C14: DAWSYN | D14: 12
... A30: 1 | B30: Stat Sandwich | C30: Minor Legalities | D30: 28

Sheet AC (Dumpster Fires)
B1: 2025 | C1: FINAL Roster | H1: BUDGET INFO. | M1: =CONCATENATE("Alan Campbell - Year",$B$1-2006," CONTRACT SHEET")
B3: 1B,CI | H3: =CONCATENATE($B$1," Base Draft Budget") | K3: 400 | M3: 2025 | O3: Player | Q3: Original Price | S3: Year Signed | U3: # of Years | W3: Years Left | Y3: Final Year | AA3: Price per year
B4: 1B,CI
B5: 1B,CI
B6: 2B,3B,CI,MI,OF | M6: 1st player contract -->> | O6: Adley Rutschman | Q6: 5 | S6: 2023 | U6: 7 | W6: =Y6-$B$1 | Y6: =S6+U6 | AA6: =IF(S6>=2014, IF(W6=0,0,IF(U6=1,Q6,IF(U6=2,Q6+5,IF(U6=3,Q6+10,IF(U6=4,Q6+15, IF(U6>4,Q6+U6*4)))))), IF(W6=0,0,IF(U6=1,Q6,IF(U6=2,Q6+4,IF(U6=3,Q6+8,IF(U6>3,Q6+U6*3))))))
B7: 2B,3B,SS,CI,MI
B8: 3B,CI | H8: =CONCATENATE("Starting ",$B$1+1," Draft Budget") | K8: =K3+K5
B9: 3B,CI | M9: 2nd player contract -->> | O9: Orion Kerkering | Q9: 0 | S9: 2024 | U9: 2 | W9: =Y9-$B$1 | Y9: =S9+U9 | AA9: =IF(S9>=2014, IF(W9=0,0,IF(U9=1,Q9,IF(U9=2,Q9+5,IF(U9=3,Q9+10,IF(U9=4,Q9+15, IF(U9>4,Q9+U9*4)))))), IF(W9=0,0,IF(U9=1,Q9,IF(U9=2,Q9+4,IF(U9=3,Q9+8,IF(U9>3,Q9+U9*3))))))
B10: C
B11: C
B12: C | H12: Regular Contracts | K12: =SUM(AA6:AA49) | M12: 3rd player contract -->> | O12: Brent Rooker | Q12: 2 | S12: 2024 | U12: 3 | W12: =Y12-$B$1 | Y12: =S12+U12 | AA12: =IF(S12>=2014, IF(W12=0,0,IF(U12=1,Q12,IF(U12=2,Q12+5,IF(U12=3,Q12+10,IF(U12=4,Q12+15, IF(U12>4,Q12+U12*4)))))), IF(W12=0,0,IF(U12=1,Q12,IF(U12=2,Q12+4,IF(U12=3,Q12+8,IF(U12>3,Q12+U12*3))))))
B13: C
B14: OF | H14: Bad Contracts | K14: =SUM(AA57,AA67,AA74,AA81)
B15: OF | M15: 4th player contract -->> | O15: Elly de la Cruz | Q15: 4 | S15: 2024 | U15: 7 | W15: =Y15-$B$1 | Y15: =S15+U15 | AA15: =IF(S15>=2014, IF(W15=0,0,IF(U15=1,Q15,IF(U15=2,Q15+5,IF(U15=3,Q15+10,IF(U15=4,Q15+15, IF(U15>4,Q15+U15*4)))))), IF(W15=0,0,IF(U15=1,Q15,IF(U15=2,Q15+4,IF(U15=3,Q15+8,IF(U15>3,Q15+U15*3))))))
B16: OF | H16: Farm Contracts | K16: =SUM(F38:F59)
B17: OF
